[2019-10-26 11:09:27] ERROR    Exception on /uploadajax [POST]
Traceback (most recent call last):
  File "/Users/davemagarian/PycharmProjects/Meme-Flask/venv/lib/python3.7/site-packages/flask/app.py", line 2446, in wsgi_app
    response = self.full_dispatch_request()
  File "/Users/davemagarian/PycharmProjects/Meme-Flask/venv/lib/python3.7/site-packages/flask/app.py", line 1951, in full_dispatch_request
    rv = self.handle_user_exception(e)
  File "/Users/davemagarian/PycharmProjects/Meme-Flask/venv/lib/python3.7/site-packages/flask/app.py", line 1820, in handle_user_exception
    reraise(exc_type, exc_value, tb)
  File "/Users/davemagarian/PycharmProjects/Meme-Flask/venv/lib/python3.7/site-packages/flask/_compat.py", line 39, in reraise
    raise value
  File "/Users/davemagarian/PycharmProjects/Meme-Flask/venv/lib/python3.7/site-packages/flask/app.py", line 1949, in full_dispatch_request
    rv = self.dispatch_request()
  File "/Users/davemagarian/PycharmProjects/Meme-Flask/venv/lib/python3.7/site-packages/flask/app.py", line 1935, in dispatch_request
    return self.view_functions[rule.endpoint](**req.view_args)
  File "/Users/davemagarian/PycharmProjects/Meme-Flask/app/views.py", line 125, in upldfile
    my_bucket = s3_resource.Bucket(S3_BUCKET)
  File "/Users/davemagarian/PycharmProjects/Meme-Flask/venv/lib/python3.7/site-packages/boto3/resources/factory.py", line 474, in create_resource
    client=self.meta.client)(*args, **kwargs)
  File "/Users/davemagarian/PycharmProjects/Meme-Flask/venv/lib/python3.7/site-packages/boto3/resources/base.py", line 119, in __init__
    'Required parameter {0} not set'.format(identifier))
ValueError: Required parameter name not set
[2019-10-26 11:11:13] ERROR    Exception on /uploadajax [POST]
Traceback (most recent call last):
  File "/Users/davemagarian/PycharmProjects/Meme-Flask/venv/lib/python3.7/site-packages/flask/app.py", line 2446, in wsgi_app
    response = self.full_dispatch_request()
  File "/Users/davemagarian/PycharmProjects/Meme-Flask/venv/lib/python3.7/site-packages/flask/app.py", line 1951, in full_dispatch_request
    rv = self.handle_user_exception(e)
  File "/Users/davemagarian/PycharmProjects/Meme-Flask/venv/lib/python3.7/site-packages/flask/app.py", line 1820, in handle_user_exception
    reraise(exc_type, exc_value, tb)
  File "/Users/davemagarian/PycharmProjects/Meme-Flask/venv/lib/python3.7/site-packages/flask/_compat.py", line 39, in reraise
    raise value
  File "/Users/davemagarian/PycharmProjects/Meme-Flask/venv/lib/python3.7/site-packages/flask/app.py", line 1949, in full_dispatch_request
    rv = self.dispatch_request()
  File "/Users/davemagarian/PycharmProjects/Meme-Flask/venv/lib/python3.7/site-packages/flask/app.py", line 1935, in dispatch_request
    return self.view_functions[rule.endpoint](**req.view_args)
  File "/Users/davemagarian/PycharmProjects/Meme-Flask/app/views.py", line 125, in upldfile
    my_bucket = s3_resource.Bucket(S3_BUCKET)
  File "/Users/davemagarian/PycharmProjects/Meme-Flask/venv/lib/python3.7/site-packages/boto3/resources/factory.py", line 474, in create_resource
    client=self.meta.client)(*args, **kwargs)
  File "/Users/davemagarian/PycharmProjects/Meme-Flask/venv/lib/python3.7/site-packages/boto3/resources/base.py", line 119, in __init__
    'Required parameter {0} not set'.format(identifier))
ValueError: Required parameter name not set
[2019-10-26 11:12:30] ERROR    Exception on /uploadajax [POST]
Traceback (most recent call last):
  File "/Users/davemagarian/PycharmProjects/Meme-Flask/venv/lib/python3.7/site-packages/flask/app.py", line 2446, in wsgi_app
    response = self.full_dispatch_request()
  File "/Users/davemagarian/PycharmProjects/Meme-Flask/venv/lib/python3.7/site-packages/flask/app.py", line 1951, in full_dispatch_request
    rv = self.handle_user_exception(e)
  File "/Users/davemagarian/PycharmProjects/Meme-Flask/venv/lib/python3.7/site-packages/flask/app.py", line 1820, in handle_user_exception
    reraise(exc_type, exc_value, tb)
  File "/Users/davemagarian/PycharmProjects/Meme-Flask/venv/lib/python3.7/site-packages/flask/_compat.py", line 39, in reraise
    raise value
  File "/Users/davemagarian/PycharmProjects/Meme-Flask/venv/lib/python3.7/site-packages/flask/app.py", line 1949, in full_dispatch_request
    rv = self.dispatch_request()
  File "/Users/davemagarian/PycharmProjects/Meme-Flask/venv/lib/python3.7/site-packages/flask/app.py", line 1935, in dispatch_request
    return self.view_functions[rule.endpoint](**req.view_args)
  File "/Users/davemagarian/PycharmProjects/Meme-Flask/app/views.py", line 125, in upldfile
    my_bucket = s3_resource.Bucket(S3_BUCKET)
  File "/Users/davemagarian/PycharmProjects/Meme-Flask/venv/lib/python3.7/site-packages/boto3/resources/factory.py", line 474, in create_resource
    client=self.meta.client)(*args, **kwargs)
  File "/Users/davemagarian/PycharmProjects/Meme-Flask/venv/lib/python3.7/site-packages/boto3/resources/base.py", line 119, in __init__
    'Required parameter {0} not set'.format(identifier))
ValueError: Required parameter name not set
[2019-10-26 11:14:38] ERROR    Exception on /uploadajax [POST]
Traceback (most recent call last):
  File "/Users/davemagarian/PycharmProjects/Meme-Flask/venv/lib/python3.7/site-packages/flask/app.py", line 2446, in wsgi_app
    response = self.full_dispatch_request()
  File "/Users/davemagarian/PycharmProjects/Meme-Flask/venv/lib/python3.7/site-packages/flask/app.py", line 1951, in full_dispatch_request
    rv = self.handle_user_exception(e)
  File "/Users/davemagarian/PycharmProjects/Meme-Flask/venv/lib/python3.7/site-packages/flask/app.py", line 1820, in handle_user_exception
    reraise(exc_type, exc_value, tb)
  File "/Users/davemagarian/PycharmProjects/Meme-Flask/venv/lib/python3.7/site-packages/flask/_compat.py", line 39, in reraise
    raise value
  File "/Users/davemagarian/PycharmProjects/Meme-Flask/venv/lib/python3.7/site-packages/flask/app.py", line 1949, in full_dispatch_request
    rv = self.dispatch_request()
  File "/Users/davemagarian/PycharmProjects/Meme-Flask/venv/lib/python3.7/site-packages/flask/app.py", line 1935, in dispatch_request
    return self.view_functions[rule.endpoint](**req.view_args)
  File "/Users/davemagarian/PycharmProjects/Meme-Flask/app/views.py", line 126, in upldfile
    my_bucket = s3_resource.Bucket(S3_BUCKET)
  File "/Users/davemagarian/PycharmProjects/Meme-Flask/venv/lib/python3.7/site-packages/boto3/resources/factory.py", line 474, in create_resource
    client=self.meta.client)(*args, **kwargs)
  File "/Users/davemagarian/PycharmProjects/Meme-Flask/venv/lib/python3.7/site-packages/boto3/resources/base.py", line 119, in __init__
    'Required parameter {0} not set'.format(identifier))
ValueError: Required parameter name not set
[2019-10-26 12:01:05] ERROR    Exception on /uploadajax [POST]
Traceback (most recent call last):
  File "/Users/davemagarian/PycharmProjects/Meme-Flask/venv/lib/python3.7/site-packages/flask/app.py", line 2446, in wsgi_app
    response = self.full_dispatch_request()
  File "/Users/davemagarian/PycharmProjects/Meme-Flask/venv/lib/python3.7/site-packages/flask/app.py", line 1951, in full_dispatch_request
    rv = self.handle_user_exception(e)
  File "/Users/davemagarian/PycharmProjects/Meme-Flask/venv/lib/python3.7/site-packages/flask/app.py", line 1820, in handle_user_exception
    reraise(exc_type, exc_value, tb)
  File "/Users/davemagarian/PycharmProjects/Meme-Flask/venv/lib/python3.7/site-packages/flask/_compat.py", line 39, in reraise
    raise value
  File "/Users/davemagarian/PycharmProjects/Meme-Flask/venv/lib/python3.7/site-packages/flask/app.py", line 1949, in full_dispatch_request
    rv = self.dispatch_request()
  File "/Users/davemagarian/PycharmProjects/Meme-Flask/venv/lib/python3.7/site-packages/flask/app.py", line 1935, in dispatch_request
    return self.view_functions[rule.endpoint](**req.view_args)
  File "/Users/davemagarian/PycharmProjects/Meme-Flask/app/views.py", line 120, in upldfile
    my_bucket = s3_resource.Bucket(S3_BUCKET)
  File "/Users/davemagarian/PycharmProjects/Meme-Flask/venv/lib/python3.7/site-packages/boto3/resources/factory.py", line 474, in create_resource
    client=self.meta.client)(*args, **kwargs)
  File "/Users/davemagarian/PycharmProjects/Meme-Flask/venv/lib/python3.7/site-packages/boto3/resources/base.py", line 119, in __init__
    'Required parameter {0} not set'.format(identifier))
ValueError: Required parameter name not set
[2019-10-26 12:01:58] ERROR    Exception on /uploadajax [POST]
Traceback (most recent call last):
  File "/Users/davemagarian/PycharmProjects/Meme-Flask/venv/lib/python3.7/site-packages/flask/app.py", line 2446, in wsgi_app
    response = self.full_dispatch_request()
  File "/Users/davemagarian/PycharmProjects/Meme-Flask/venv/lib/python3.7/site-packages/flask/app.py", line 1951, in full_dispatch_request
    rv = self.handle_user_exception(e)
  File "/Users/davemagarian/PycharmProjects/Meme-Flask/venv/lib/python3.7/site-packages/flask/app.py", line 1820, in handle_user_exception
    reraise(exc_type, exc_value, tb)
  File "/Users/davemagarian/PycharmProjects/Meme-Flask/venv/lib/python3.7/site-packages/flask/_compat.py", line 39, in reraise
    raise value
  File "/Users/davemagarian/PycharmProjects/Meme-Flask/venv/lib/python3.7/site-packages/flask/app.py", line 1949, in full_dispatch_request
    rv = self.dispatch_request()
  File "/Users/davemagarian/PycharmProjects/Meme-Flask/venv/lib/python3.7/site-packages/flask/app.py", line 1935, in dispatch_request
    return self.view_functions[rule.endpoint](**req.view_args)
  File "/Users/davemagarian/PycharmProjects/Meme-Flask/app/views.py", line 120, in upldfile
    my_bucket = s3_resource.Bucket(S3_BUCKET)
  File "/Users/davemagarian/PycharmProjects/Meme-Flask/venv/lib/python3.7/site-packages/boto3/resources/factory.py", line 474, in create_resource
    client=self.meta.client)(*args, **kwargs)
  File "/Users/davemagarian/PycharmProjects/Meme-Flask/venv/lib/python3.7/site-packages/boto3/resources/base.py", line 119, in __init__
    'Required parameter {0} not set'.format(identifier))
ValueError: Required parameter name not set
[2019-10-26 12:13:46] ERROR    Exception on /uploadajax [POST]
Traceback (most recent call last):
  File "/Users/davemagarian/PycharmProjects/Meme-Flask/venv/lib/python3.7/site-packages/flask/app.py", line 2446, in wsgi_app
    response = self.full_dispatch_request()
  File "/Users/davemagarian/PycharmProjects/Meme-Flask/venv/lib/python3.7/site-packages/flask/app.py", line 1951, in full_dispatch_request
    rv = self.handle_user_exception(e)
  File "/Users/davemagarian/PycharmProjects/Meme-Flask/venv/lib/python3.7/site-packages/flask/app.py", line 1820, in handle_user_exception
    reraise(exc_type, exc_value, tb)
  File "/Users/davemagarian/PycharmProjects/Meme-Flask/venv/lib/python3.7/site-packages/flask/_compat.py", line 39, in reraise
    raise value
  File "/Users/davemagarian/PycharmProjects/Meme-Flask/venv/lib/python3.7/site-packages/flask/app.py", line 1949, in full_dispatch_request
    rv = self.dispatch_request()
  File "/Users/davemagarian/PycharmProjects/Meme-Flask/venv/lib/python3.7/site-packages/flask/app.py", line 1935, in dispatch_request
    return self.view_functions[rule.endpoint](**req.view_args)
  File "/Users/davemagarian/PycharmProjects/Meme-Flask/app/views.py", line 117, in upldfile
    my_bucket = s3_resource.Bucket(S3_BUCKET)
  File "/Users/davemagarian/PycharmProjects/Meme-Flask/venv/lib/python3.7/site-packages/boto3/resources/factory.py", line 474, in create_resource
    client=self.meta.client)(*args, **kwargs)
  File "/Users/davemagarian/PycharmProjects/Meme-Flask/venv/lib/python3.7/site-packages/boto3/resources/base.py", line 119, in __init__
    'Required parameter {0} not set'.format(identifier))
ValueError: Required parameter name not set
[2019-10-26 12:15:59] ERROR    Exception on /uploadajax [POST]
Traceback (most recent call last):
  File "/Users/davemagarian/PycharmProjects/Meme-Flask/venv/lib/python3.7/site-packages/flask/app.py", line 2446, in wsgi_app
    response = self.full_dispatch_request()
  File "/Users/davemagarian/PycharmProjects/Meme-Flask/venv/lib/python3.7/site-packages/flask/app.py", line 1951, in full_dispatch_request
    rv = self.handle_user_exception(e)
  File "/Users/davemagarian/PycharmProjects/Meme-Flask/venv/lib/python3.7/site-packages/flask/app.py", line 1820, in handle_user_exception
    reraise(exc_type, exc_value, tb)
  File "/Users/davemagarian/PycharmProjects/Meme-Flask/venv/lib/python3.7/site-packages/flask/_compat.py", line 39, in reraise
    raise value
  File "/Users/davemagarian/PycharmProjects/Meme-Flask/venv/lib/python3.7/site-packages/flask/app.py", line 1949, in full_dispatch_request
    rv = self.dispatch_request()
  File "/Users/davemagarian/PycharmProjects/Meme-Flask/venv/lib/python3.7/site-packages/flask/app.py", line 1935, in dispatch_request
    return self.view_functions[rule.endpoint](**req.view_args)
  File "/Users/davemagarian/PycharmProjects/Meme-Flask/app/views.py", line 117, in upldfile
    my_bucket = s3_resource.Bucket(S3_BUCKET)
  File "/Users/davemagarian/PycharmProjects/Meme-Flask/venv/lib/python3.7/site-packages/boto3/resources/factory.py", line 474, in create_resource
    client=self.meta.client)(*args, **kwargs)
  File "/Users/davemagarian/PycharmProjects/Meme-Flask/venv/lib/python3.7/site-packages/boto3/resources/base.py", line 119, in __init__
    'Required parameter {0} not set'.format(identifier))
ValueError: Required parameter name not set
[2019-10-26 12:16:22] ERROR    Exception on /uploadajax [POST]
Traceback (most recent call last):
  File "/Users/davemagarian/PycharmProjects/Meme-Flask/venv/lib/python3.7/site-packages/flask/app.py", line 2446, in wsgi_app
    response = self.full_dispatch_request()
  File "/Users/davemagarian/PycharmProjects/Meme-Flask/venv/lib/python3.7/site-packages/flask/app.py", line 1951, in full_dispatch_request
    rv = self.handle_user_exception(e)
  File "/Users/davemagarian/PycharmProjects/Meme-Flask/venv/lib/python3.7/site-packages/flask/app.py", line 1820, in handle_user_exception
    reraise(exc_type, exc_value, tb)
  File "/Users/davemagarian/PycharmProjects/Meme-Flask/venv/lib/python3.7/site-packages/flask/_compat.py", line 39, in reraise
    raise value
  File "/Users/davemagarian/PycharmProjects/Meme-Flask/venv/lib/python3.7/site-packages/flask/app.py", line 1949, in full_dispatch_request
    rv = self.dispatch_request()
  File "/Users/davemagarian/PycharmProjects/Meme-Flask/venv/lib/python3.7/site-packages/flask/app.py", line 1935, in dispatch_request
    return self.view_functions[rule.endpoint](**req.view_args)
  File "/Users/davemagarian/PycharmProjects/Meme-Flask/app/views.py", line 117, in upldfile
    my_bucket = s3_resource.Bucket(S3_BUCKET)
  File "/Users/davemagarian/PycharmProjects/Meme-Flask/venv/lib/python3.7/site-packages/boto3/resources/factory.py", line 474, in create_resource
    client=self.meta.client)(*args, **kwargs)
  File "/Users/davemagarian/PycharmProjects/Meme-Flask/venv/lib/python3.7/site-packages/boto3/resources/base.py", line 119, in __init__
    'Required parameter {0} not set'.format(identifier))
ValueError: Required parameter name not set
[2019-10-26 12:17:49] ERROR    Exception on /uploadajax [POST]
Traceback (most recent call last):
  File "/Users/davemagarian/PycharmProjects/Meme-Flask/venv/lib/python3.7/site-packages/flask/app.py", line 2446, in wsgi_app
    response = self.full_dispatch_request()
  File "/Users/davemagarian/PycharmProjects/Meme-Flask/venv/lib/python3.7/site-packages/flask/app.py", line 1951, in full_dispatch_request
    rv = self.handle_user_exception(e)
  File "/Users/davemagarian/PycharmProjects/Meme-Flask/venv/lib/python3.7/site-packages/flask/app.py", line 1820, in handle_user_exception
    reraise(exc_type, exc_value, tb)
  File "/Users/davemagarian/PycharmProjects/Meme-Flask/venv/lib/python3.7/site-packages/flask/_compat.py", line 39, in reraise
    raise value
  File "/Users/davemagarian/PycharmProjects/Meme-Flask/venv/lib/python3.7/site-packages/flask/app.py", line 1949, in full_dispatch_request
    rv = self.dispatch_request()
  File "/Users/davemagarian/PycharmProjects/Meme-Flask/venv/lib/python3.7/site-packages/flask/app.py", line 1935, in dispatch_request
    return self.view_functions[rule.endpoint](**req.view_args)
  File "/Users/davemagarian/PycharmProjects/Meme-Flask/app/views.py", line 117, in upldfile
    my_bucket = s3_resource.Bucket('satoshismemes')
  File "/Users/davemagarian/PycharmProjects/Meme-Flask/venv/lib/python3.7/site-packages/boto3/resources/factory.py", line 474, in create_resource
    client=self.meta.client)(*args, **kwargs)
  File "/Users/davemagarian/PycharmProjects/Meme-Flask/venv/lib/python3.7/site-packages/boto3/resources/base.py", line 119, in __init__
    'Required parameter {0} not set'.format(identifier))
ValueError: Required parameter name not set
[2019-10-26 12:18:23] ERROR    Exception on /uploadajax [POST]
Traceback (most recent call last):
  File "/Users/davemagarian/PycharmProjects/Meme-Flask/venv/lib/python3.7/site-packages/flask/app.py", line 2446, in wsgi_app
    response = self.full_dispatch_request()
  File "/Users/davemagarian/PycharmProjects/Meme-Flask/venv/lib/python3.7/site-packages/flask/app.py", line 1951, in full_dispatch_request
    rv = self.handle_user_exception(e)
  File "/Users/davemagarian/PycharmProjects/Meme-Flask/venv/lib/python3.7/site-packages/flask/app.py", line 1820, in handle_user_exception
    reraise(exc_type, exc_value, tb)
  File "/Users/davemagarian/PycharmProjects/Meme-Flask/venv/lib/python3.7/site-packages/flask/_compat.py", line 39, in reraise
    raise value
  File "/Users/davemagarian/PycharmProjects/Meme-Flask/venv/lib/python3.7/site-packages/flask/app.py", line 1949, in full_dispatch_request
    rv = self.dispatch_request()
  File "/Users/davemagarian/PycharmProjects/Meme-Flask/venv/lib/python3.7/site-packages/flask/app.py", line 1935, in dispatch_request
    return self.view_functions[rule.endpoint](**req.view_args)
  File "/Users/davemagarian/PycharmProjects/Meme-Flask/app/views.py", line 118, in upldfile
    my_bucket.Object(filename).put(Body=filename)
  File "/Users/davemagarian/PycharmProjects/Meme-Flask/venv/lib/python3.7/site-packages/boto3/resources/factory.py", line 520, in do_action
    response = action(self, *args, **kwargs)
  File "/Users/davemagarian/PycharmProjects/Meme-Flask/venv/lib/python3.7/site-packages/boto3/resources/action.py", line 83, in __call__
    response = getattr(parent.meta.client, operation_name)(**params)
  File "/Users/davemagarian/PycharmProjects/Meme-Flask/venv/lib/python3.7/site-packages/botocore/client.py", line 357, in _api_call
    return self._make_api_call(operation_name, kwargs)
  File "/Users/davemagarian/PycharmProjects/Meme-Flask/venv/lib/python3.7/site-packages/botocore/client.py", line 648, in _make_api_call
    operation_model, request_dict, request_context)
  File "/Users/davemagarian/PycharmProjects/Meme-Flask/venv/lib/python3.7/site-packages/botocore/client.py", line 667, in _make_request
    return self._endpoint.make_request(operation_model, request_dict)
  File "/Users/davemagarian/PycharmProjects/Meme-Flask/venv/lib/python3.7/site-packages/botocore/endpoint.py", line 102, in make_request
    return self._send_request(request_dict, operation_model)
  File "/Users/davemagarian/PycharmProjects/Meme-Flask/venv/lib/python3.7/site-packages/botocore/endpoint.py", line 132, in _send_request
    request = self.create_request(request_dict, operation_model)
  File "/Users/davemagarian/PycharmProjects/Meme-Flask/venv/lib/python3.7/site-packages/botocore/endpoint.py", line 116, in create_request
    operation_name=operation_model.name)
  File "/Users/davemagarian/PycharmProjects/Meme-Flask/venv/lib/python3.7/site-packages/botocore/hooks.py", line 356, in emit
    return self._emitter.emit(aliased_event_name, **kwargs)
  File "/Users/davemagarian/PycharmProjects/Meme-Flask/venv/lib/python3.7/site-packages/botocore/hooks.py", line 228, in emit
    return self._emit(event_name, kwargs)
  File "/Users/davemagarian/PycharmProjects/Meme-Flask/venv/lib/python3.7/site-packages/botocore/hooks.py", line 211, in _emit
    response = handler(**kwargs)
  File "/Users/davemagarian/PycharmProjects/Meme-Flask/venv/lib/python3.7/site-packages/botocore/signers.py", line 90, in handler
    return self.sign(operation_name, request)
  File "/Users/davemagarian/PycharmProjects/Meme-Flask/venv/lib/python3.7/site-packages/botocore/signers.py", line 157, in sign
    auth.add_auth(request)
  File "/Users/davemagarian/PycharmProjects/Meme-Flask/venv/lib/python3.7/site-packages/botocore/auth.py", line 425, in add_auth
    super(S3SigV4Auth, self).add_auth(request)
  File "/Users/davemagarian/PycharmProjects/Meme-Flask/venv/lib/python3.7/site-packages/botocore/auth.py", line 357, in add_auth
    raise NoCredentialsError
botocore.exceptions.NoCredentialsError: Unable to locate credentials
[2019-10-26 12:20:15] ERROR    Exception on /uploadajax [POST]
Traceback (most recent call last):
  File "/Users/davemagarian/PycharmProjects/Meme-Flask/venv/lib/python3.7/site-packages/flask/app.py", line 2446, in wsgi_app
    response = self.full_dispatch_request()
  File "/Users/davemagarian/PycharmProjects/Meme-Flask/venv/lib/python3.7/site-packages/flask/app.py", line 1951, in full_dispatch_request
    rv = self.handle_user_exception(e)
  File "/Users/davemagarian/PycharmProjects/Meme-Flask/venv/lib/python3.7/site-packages/flask/app.py", line 1820, in handle_user_exception
    reraise(exc_type, exc_value, tb)
  File "/Users/davemagarian/PycharmProjects/Meme-Flask/venv/lib/python3.7/site-packages/flask/_compat.py", line 39, in reraise
    raise value
  File "/Users/davemagarian/PycharmProjects/Meme-Flask/venv/lib/python3.7/site-packages/flask/app.py", line 1949, in full_dispatch_request
    rv = self.dispatch_request()
  File "/Users/davemagarian/PycharmProjects/Meme-Flask/venv/lib/python3.7/site-packages/flask/app.py", line 1935, in dispatch_request
    return self.view_functions[rule.endpoint](**req.view_args)
  File "/Users/davemagarian/PycharmProjects/Meme-Flask/app/views.py", line 118, in upldfile
    my_bucket.Object(filename).put(Body=filename)
  File "/Users/davemagarian/PycharmProjects/Meme-Flask/venv/lib/python3.7/site-packages/boto3/resources/factory.py", line 520, in do_action
    response = action(self, *args, **kwargs)
  File "/Users/davemagarian/PycharmProjects/Meme-Flask/venv/lib/python3.7/site-packages/boto3/resources/action.py", line 83, in __call__
    response = getattr(parent.meta.client, operation_name)(**params)
  File "/Users/davemagarian/PycharmProjects/Meme-Flask/venv/lib/python3.7/site-packages/botocore/client.py", line 357, in _api_call
    return self._make_api_call(operation_name, kwargs)
  File "/Users/davemagarian/PycharmProjects/Meme-Flask/venv/lib/python3.7/site-packages/botocore/client.py", line 648, in _make_api_call
    operation_model, request_dict, request_context)
  File "/Users/davemagarian/PycharmProjects/Meme-Flask/venv/lib/python3.7/site-packages/botocore/client.py", line 667, in _make_request
    return self._endpoint.make_request(operation_model, request_dict)
  File "/Users/davemagarian/PycharmProjects/Meme-Flask/venv/lib/python3.7/site-packages/botocore/endpoint.py", line 102, in make_request
    return self._send_request(request_dict, operation_model)
  File "/Users/davemagarian/PycharmProjects/Meme-Flask/venv/lib/python3.7/site-packages/botocore/endpoint.py", line 132, in _send_request
    request = self.create_request(request_dict, operation_model)
  File "/Users/davemagarian/PycharmProjects/Meme-Flask/venv/lib/python3.7/site-packages/botocore/endpoint.py", line 116, in create_request
    operation_name=operation_model.name)
  File "/Users/davemagarian/PycharmProjects/Meme-Flask/venv/lib/python3.7/site-packages/botocore/hooks.py", line 356, in emit
    return self._emitter.emit(aliased_event_name, **kwargs)
  File "/Users/davemagarian/PycharmProjects/Meme-Flask/venv/lib/python3.7/site-packages/botocore/hooks.py", line 228, in emit
    return self._emit(event_name, kwargs)
  File "/Users/davemagarian/PycharmProjects/Meme-Flask/venv/lib/python3.7/site-packages/botocore/hooks.py", line 211, in _emit
    response = handler(**kwargs)
  File "/Users/davemagarian/PycharmProjects/Meme-Flask/venv/lib/python3.7/site-packages/botocore/signers.py", line 90, in handler
    return self.sign(operation_name, request)
  File "/Users/davemagarian/PycharmProjects/Meme-Flask/venv/lib/python3.7/site-packages/botocore/signers.py", line 157, in sign
    auth.add_auth(request)
  File "/Users/davemagarian/PycharmProjects/Meme-Flask/venv/lib/python3.7/site-packages/botocore/auth.py", line 425, in add_auth
    super(S3SigV4Auth, self).add_auth(request)
  File "/Users/davemagarian/PycharmProjects/Meme-Flask/venv/lib/python3.7/site-packages/botocore/auth.py", line 357, in add_auth
    raise NoCredentialsError
botocore.exceptions.NoCredentialsError: Unable to locate credentials
[2019-10-26 12:21:24] ERROR    Exception on /uploadajax [POST]
Traceback (most recent call last):
  File "/Users/davemagarian/PycharmProjects/Meme-Flask/venv/lib/python3.7/site-packages/flask/app.py", line 2446, in wsgi_app
    response = self.full_dispatch_request()
  File "/Users/davemagarian/PycharmProjects/Meme-Flask/venv/lib/python3.7/site-packages/flask/app.py", line 1951, in full_dispatch_request
    rv = self.handle_user_exception(e)
  File "/Users/davemagarian/PycharmProjects/Meme-Flask/venv/lib/python3.7/site-packages/flask/app.py", line 1820, in handle_user_exception
    reraise(exc_type, exc_value, tb)
  File "/Users/davemagarian/PycharmProjects/Meme-Flask/venv/lib/python3.7/site-packages/flask/_compat.py", line 39, in reraise
    raise value
  File "/Users/davemagarian/PycharmProjects/Meme-Flask/venv/lib/python3.7/site-packages/flask/app.py", line 1949, in full_dispatch_request
    rv = self.dispatch_request()
  File "/Users/davemagarian/PycharmProjects/Meme-Flask/venv/lib/python3.7/site-packages/flask/app.py", line 1935, in dispatch_request
    return self.view_functions[rule.endpoint](**req.view_args)
  File "/Users/davemagarian/PycharmProjects/Meme-Flask/app/views.py", line 118, in upldfile
    my_bucket.Object(filename).put(Body=filename)
  File "/Users/davemagarian/PycharmProjects/Meme-Flask/venv/lib/python3.7/site-packages/boto3/resources/factory.py", line 520, in do_action
    response = action(self, *args, **kwargs)
  File "/Users/davemagarian/PycharmProjects/Meme-Flask/venv/lib/python3.7/site-packages/boto3/resources/action.py", line 83, in __call__
    response = getattr(parent.meta.client, operation_name)(**params)
  File "/Users/davemagarian/PycharmProjects/Meme-Flask/venv/lib/python3.7/site-packages/botocore/client.py", line 357, in _api_call
    return self._make_api_call(operation_name, kwargs)
  File "/Users/davemagarian/PycharmProjects/Meme-Flask/venv/lib/python3.7/site-packages/botocore/client.py", line 648, in _make_api_call
    operation_model, request_dict, request_context)
  File "/Users/davemagarian/PycharmProjects/Meme-Flask/venv/lib/python3.7/site-packages/botocore/client.py", line 667, in _make_request
    return self._endpoint.make_request(operation_model, request_dict)
  File "/Users/davemagarian/PycharmProjects/Meme-Flask/venv/lib/python3.7/site-packages/botocore/endpoint.py", line 102, in make_request
    return self._send_request(request_dict, operation_model)
  File "/Users/davemagarian/PycharmProjects/Meme-Flask/venv/lib/python3.7/site-packages/botocore/endpoint.py", line 132, in _send_request
    request = self.create_request(request_dict, operation_model)
  File "/Users/davemagarian/PycharmProjects/Meme-Flask/venv/lib/python3.7/site-packages/botocore/endpoint.py", line 116, in create_request
    operation_name=operation_model.name)
  File "/Users/davemagarian/PycharmProjects/Meme-Flask/venv/lib/python3.7/site-packages/botocore/hooks.py", line 356, in emit
    return self._emitter.emit(aliased_event_name, **kwargs)
  File "/Users/davemagarian/PycharmProjects/Meme-Flask/venv/lib/python3.7/site-packages/botocore/hooks.py", line 228, in emit
    return self._emit(event_name, kwargs)
  File "/Users/davemagarian/PycharmProjects/Meme-Flask/venv/lib/python3.7/site-packages/botocore/hooks.py", line 211, in _emit
    response = handler(**kwargs)
  File "/Users/davemagarian/PycharmProjects/Meme-Flask/venv/lib/python3.7/site-packages/botocore/signers.py", line 90, in handler
    return self.sign(operation_name, request)
  File "/Users/davemagarian/PycharmProjects/Meme-Flask/venv/lib/python3.7/site-packages/botocore/signers.py", line 157, in sign
    auth.add_auth(request)
  File "/Users/davemagarian/PycharmProjects/Meme-Flask/venv/lib/python3.7/site-packages/botocore/auth.py", line 425, in add_auth
    super(S3SigV4Auth, self).add_auth(request)
  File "/Users/davemagarian/PycharmProjects/Meme-Flask/venv/lib/python3.7/site-packages/botocore/auth.py", line 357, in add_auth
    raise NoCredentialsError
botocore.exceptions.NoCredentialsError: Unable to locate credentials
[2019-10-26 12:23:03] ERROR    Exception on /uploadajax [POST]
Traceback (most recent call last):
  File "/Users/davemagarian/PycharmProjects/Meme-Flask/venv/lib/python3.7/site-packages/flask/app.py", line 2446, in wsgi_app
    response = self.full_dispatch_request()
  File "/Users/davemagarian/PycharmProjects/Meme-Flask/venv/lib/python3.7/site-packages/flask/app.py", line 1951, in full_dispatch_request
    rv = self.handle_user_exception(e)
  File "/Users/davemagarian/PycharmProjects/Meme-Flask/venv/lib/python3.7/site-packages/flask/app.py", line 1820, in handle_user_exception
    reraise(exc_type, exc_value, tb)
  File "/Users/davemagarian/PycharmProjects/Meme-Flask/venv/lib/python3.7/site-packages/flask/_compat.py", line 39, in reraise
    raise value
  File "/Users/davemagarian/PycharmProjects/Meme-Flask/venv/lib/python3.7/site-packages/flask/app.py", line 1949, in full_dispatch_request
    rv = self.dispatch_request()
  File "/Users/davemagarian/PycharmProjects/Meme-Flask/venv/lib/python3.7/site-packages/flask/app.py", line 1935, in dispatch_request
    return self.view_functions[rule.endpoint](**req.view_args)
  File "/Users/davemagarian/PycharmProjects/Meme-Flask/app/views.py", line 118, in upldfile
    my_bucket.Object(filename).put(Body=filename)
  File "/Users/davemagarian/PycharmProjects/Meme-Flask/venv/lib/python3.7/site-packages/boto3/resources/factory.py", line 520, in do_action
    response = action(self, *args, **kwargs)
  File "/Users/davemagarian/PycharmProjects/Meme-Flask/venv/lib/python3.7/site-packages/boto3/resources/action.py", line 83, in __call__
    response = getattr(parent.meta.client, operation_name)(**params)
  File "/Users/davemagarian/PycharmProjects/Meme-Flask/venv/lib/python3.7/site-packages/botocore/client.py", line 357, in _api_call
    return self._make_api_call(operation_name, kwargs)
  File "/Users/davemagarian/PycharmProjects/Meme-Flask/venv/lib/python3.7/site-packages/botocore/client.py", line 648, in _make_api_call
    operation_model, request_dict, request_context)
  File "/Users/davemagarian/PycharmProjects/Meme-Flask/venv/lib/python3.7/site-packages/botocore/client.py", line 667, in _make_request
    return self._endpoint.make_request(operation_model, request_dict)
  File "/Users/davemagarian/PycharmProjects/Meme-Flask/venv/lib/python3.7/site-packages/botocore/endpoint.py", line 102, in make_request
    return self._send_request(request_dict, operation_model)
  File "/Users/davemagarian/PycharmProjects/Meme-Flask/venv/lib/python3.7/site-packages/botocore/endpoint.py", line 132, in _send_request
    request = self.create_request(request_dict, operation_model)
  File "/Users/davemagarian/PycharmProjects/Meme-Flask/venv/lib/python3.7/site-packages/botocore/endpoint.py", line 116, in create_request
    operation_name=operation_model.name)
  File "/Users/davemagarian/PycharmProjects/Meme-Flask/venv/lib/python3.7/site-packages/botocore/hooks.py", line 356, in emit
    return self._emitter.emit(aliased_event_name, **kwargs)
  File "/Users/davemagarian/PycharmProjects/Meme-Flask/venv/lib/python3.7/site-packages/botocore/hooks.py", line 228, in emit
    return self._emit(event_name, kwargs)
  File "/Users/davemagarian/PycharmProjects/Meme-Flask/venv/lib/python3.7/site-packages/botocore/hooks.py", line 211, in _emit
    response = handler(**kwargs)
  File "/Users/davemagarian/PycharmProjects/Meme-Flask/venv/lib/python3.7/site-packages/botocore/signers.py", line 90, in handler
    return self.sign(operation_name, request)
  File "/Users/davemagarian/PycharmProjects/Meme-Flask/venv/lib/python3.7/site-packages/botocore/signers.py", line 157, in sign
    auth.add_auth(request)
  File "/Users/davemagarian/PycharmProjects/Meme-Flask/venv/lib/python3.7/site-packages/botocore/auth.py", line 425, in add_auth
    super(S3SigV4Auth, self).add_auth(request)
  File "/Users/davemagarian/PycharmProjects/Meme-Flask/venv/lib/python3.7/site-packages/botocore/auth.py", line 357, in add_auth
    raise NoCredentialsError
botocore.exceptions.NoCredentialsError: Unable to locate credentials
[2019-10-26 12:47:19] ERROR    Exception on /uploadajax [POST]
Traceback (most recent call last):
  File "/Users/davemagarian/PycharmProjects/Meme-Flask/venv/lib/python3.7/site-packages/flask/app.py", line 2446, in wsgi_app
    response = self.full_dispatch_request()
  File "/Users/davemagarian/PycharmProjects/Meme-Flask/venv/lib/python3.7/site-packages/flask/app.py", line 1951, in full_dispatch_request
    rv = self.handle_user_exception(e)
  File "/Users/davemagarian/PycharmProjects/Meme-Flask/venv/lib/python3.7/site-packages/flask/app.py", line 1820, in handle_user_exception
    reraise(exc_type, exc_value, tb)
  File "/Users/davemagarian/PycharmProjects/Meme-Flask/venv/lib/python3.7/site-packages/flask/_compat.py", line 39, in reraise
    raise value
  File "/Users/davemagarian/PycharmProjects/Meme-Flask/venv/lib/python3.7/site-packages/flask/app.py", line 1949, in full_dispatch_request
    rv = self.dispatch_request()
  File "/Users/davemagarian/PycharmProjects/Meme-Flask/venv/lib/python3.7/site-packages/flask/app.py", line 1935, in dispatch_request
    return self.view_functions[rule.endpoint](**req.view_args)
  File "/Users/davemagarian/PycharmProjects/Meme-Flask/app/views.py", line 125, in upldfile
    newObject.download_fileobj(file_stream)
  File "/Users/davemagarian/PycharmProjects/Meme-Flask/venv/lib/python3.7/site-packages/boto3/s3/inject.py", line 760, in object_download_fileobj
    ExtraArgs=ExtraArgs, Callback=Callback, Config=Config)
  File "/Users/davemagarian/PycharmProjects/Meme-Flask/venv/lib/python3.7/site-packages/boto3/s3/inject.py", line 678, in download_fileobj
    return future.result()
  File "/Users/davemagarian/PycharmProjects/Meme-Flask/venv/lib/python3.7/site-packages/s3transfer/futures.py", line 106, in result
    return self._coordinator.result()
  File "/Users/davemagarian/PycharmProjects/Meme-Flask/venv/lib/python3.7/site-packages/s3transfer/futures.py", line 265, in result
    raise self._exception
  File "/Users/davemagarian/PycharmProjects/Meme-Flask/venv/lib/python3.7/site-packages/s3transfer/tasks.py", line 126, in __call__
    return self._execute_main(kwargs)
  File "/Users/davemagarian/PycharmProjects/Meme-Flask/venv/lib/python3.7/site-packages/s3transfer/tasks.py", line 150, in _execute_main
    return_value = self._main(**kwargs)
  File "/Users/davemagarian/PycharmProjects/Meme-Flask/venv/lib/python3.7/site-packages/s3transfer/download.py", line 574, in _main
    fileobj.write(data)
TypeError: string argument expected, got 'bytes'
[2019-10-26 12:48:19] ERROR    Exception on /uploadajax [POST]
Traceback (most recent call last):
  File "/Users/davemagarian/PycharmProjects/Meme-Flask/venv/lib/python3.7/site-packages/flask/app.py", line 2446, in wsgi_app
    response = self.full_dispatch_request()
  File "/Users/davemagarian/PycharmProjects/Meme-Flask/venv/lib/python3.7/site-packages/flask/app.py", line 1951, in full_dispatch_request
    rv = self.handle_user_exception(e)
  File "/Users/davemagarian/PycharmProjects/Meme-Flask/venv/lib/python3.7/site-packages/flask/app.py", line 1820, in handle_user_exception
    reraise(exc_type, exc_value, tb)
  File "/Users/davemagarian/PycharmProjects/Meme-Flask/venv/lib/python3.7/site-packages/flask/_compat.py", line 39, in reraise
    raise value
  File "/Users/davemagarian/PycharmProjects/Meme-Flask/venv/lib/python3.7/site-packages/flask/app.py", line 1949, in full_dispatch_request
    rv = self.dispatch_request()
  File "/Users/davemagarian/PycharmProjects/Meme-Flask/venv/lib/python3.7/site-packages/flask/app.py", line 1935, in dispatch_request
    return self.view_functions[rule.endpoint](**req.view_args)
  File "/Users/davemagarian/PycharmProjects/Meme-Flask/app/views.py", line 125, in upldfile
    newObject.download_fileobj(file_stream)
  File "/Users/davemagarian/PycharmProjects/Meme-Flask/venv/lib/python3.7/site-packages/boto3/s3/inject.py", line 760, in object_download_fileobj
    ExtraArgs=ExtraArgs, Callback=Callback, Config=Config)
  File "/Users/davemagarian/PycharmProjects/Meme-Flask/venv/lib/python3.7/site-packages/boto3/s3/inject.py", line 678, in download_fileobj
    return future.result()
  File "/Users/davemagarian/PycharmProjects/Meme-Flask/venv/lib/python3.7/site-packages/s3transfer/futures.py", line 106, in result
    return self._coordinator.result()
  File "/Users/davemagarian/PycharmProjects/Meme-Flask/venv/lib/python3.7/site-packages/s3transfer/futures.py", line 265, in result
    raise self._exception
  File "/Users/davemagarian/PycharmProjects/Meme-Flask/venv/lib/python3.7/site-packages/s3transfer/tasks.py", line 126, in __call__
    return self._execute_main(kwargs)
  File "/Users/davemagarian/PycharmProjects/Meme-Flask/venv/lib/python3.7/site-packages/s3transfer/tasks.py", line 150, in _execute_main
    return_value = self._main(**kwargs)
  File "/Users/davemagarian/PycharmProjects/Meme-Flask/venv/lib/python3.7/site-packages/s3transfer/download.py", line 574, in _main
    fileobj.write(data)
TypeError: string argument expected, got 'bytes'
[2019-10-26 12:48:36] ERROR    Exception on /uploadajax [POST]
Traceback (most recent call last):
  File "/Users/davemagarian/PycharmProjects/Meme-Flask/venv/lib/python3.7/site-packages/flask/app.py", line 2446, in wsgi_app
    response = self.full_dispatch_request()
  File "/Users/davemagarian/PycharmProjects/Meme-Flask/venv/lib/python3.7/site-packages/flask/app.py", line 1951, in full_dispatch_request
    rv = self.handle_user_exception(e)
  File "/Users/davemagarian/PycharmProjects/Meme-Flask/venv/lib/python3.7/site-packages/flask/app.py", line 1820, in handle_user_exception
    reraise(exc_type, exc_value, tb)
  File "/Users/davemagarian/PycharmProjects/Meme-Flask/venv/lib/python3.7/site-packages/flask/_compat.py", line 39, in reraise
    raise value
  File "/Users/davemagarian/PycharmProjects/Meme-Flask/venv/lib/python3.7/site-packages/flask/app.py", line 1949, in full_dispatch_request
    rv = self.dispatch_request()
  File "/Users/davemagarian/PycharmProjects/Meme-Flask/venv/lib/python3.7/site-packages/flask/app.py", line 1935, in dispatch_request
    return self.view_functions[rule.endpoint](**req.view_args)
  File "/Users/davemagarian/PycharmProjects/Meme-Flask/app/views.py", line 126, in upldfile
    meme = mpimg.imread(file_stream)
  File "/Users/davemagarian/PycharmProjects/Meme-Flask/venv/lib/python3.7/site-packages/matplotlib/image.py", line 1436, in imread
    return handler(fname)
  File "/Users/davemagarian/PycharmProjects/Meme-Flask/venv/lib/python3.7/site-packages/matplotlib/image.py", line 1390, in read_png
    return _png.read_png(*args, **kwargs)
OSError: read past end of file
[2019-10-26 12:51:43] ERROR    Exception on /uploadajax [POST]
Traceback (most recent call last):
  File "/Users/davemagarian/PycharmProjects/Meme-Flask/venv/lib/python3.7/site-packages/flask/app.py", line 2446, in wsgi_app
    response = self.full_dispatch_request()
  File "/Users/davemagarian/PycharmProjects/Meme-Flask/venv/lib/python3.7/site-packages/flask/app.py", line 1951, in full_dispatch_request
    rv = self.handle_user_exception(e)
  File "/Users/davemagarian/PycharmProjects/Meme-Flask/venv/lib/python3.7/site-packages/flask/app.py", line 1820, in handle_user_exception
    reraise(exc_type, exc_value, tb)
  File "/Users/davemagarian/PycharmProjects/Meme-Flask/venv/lib/python3.7/site-packages/flask/_compat.py", line 39, in reraise
    raise value
  File "/Users/davemagarian/PycharmProjects/Meme-Flask/venv/lib/python3.7/site-packages/flask/app.py", line 1949, in full_dispatch_request
    rv = self.dispatch_request()
  File "/Users/davemagarian/PycharmProjects/Meme-Flask/venv/lib/python3.7/site-packages/flask/app.py", line 1935, in dispatch_request
    return self.view_functions[rule.endpoint](**req.view_args)
  File "/Users/davemagarian/PycharmProjects/Meme-Flask/app/views.py", line 126, in upldfile
    x = mpimg.imread(file_stream)
  File "/Users/davemagarian/PycharmProjects/Meme-Flask/venv/lib/python3.7/site-packages/matplotlib/image.py", line 1436, in imread
    return handler(fname)
  File "/Users/davemagarian/PycharmProjects/Meme-Flask/venv/lib/python3.7/site-packages/matplotlib/image.py", line 1390, in read_png
    return _png.read_png(*args, **kwargs)
OSError: read past end of file
[2019-10-26 12:52:28] ERROR    Exception on /uploadajax [POST]
Traceback (most recent call last):
  File "/Users/davemagarian/PycharmProjects/Meme-Flask/venv/lib/python3.7/site-packages/flask/app.py", line 2446, in wsgi_app
    response = self.full_dispatch_request()
  File "/Users/davemagarian/PycharmProjects/Meme-Flask/venv/lib/python3.7/site-packages/flask/app.py", line 1951, in full_dispatch_request
    rv = self.handle_user_exception(e)
  File "/Users/davemagarian/PycharmProjects/Meme-Flask/venv/lib/python3.7/site-packages/flask/app.py", line 1820, in handle_user_exception
    reraise(exc_type, exc_value, tb)
  File "/Users/davemagarian/PycharmProjects/Meme-Flask/venv/lib/python3.7/site-packages/flask/_compat.py", line 39, in reraise
    raise value
  File "/Users/davemagarian/PycharmProjects/Meme-Flask/venv/lib/python3.7/site-packages/flask/app.py", line 1949, in full_dispatch_request
    rv = self.dispatch_request()
  File "/Users/davemagarian/PycharmProjects/Meme-Flask/venv/lib/python3.7/site-packages/flask/app.py", line 1935, in dispatch_request
    return self.view_functions[rule.endpoint](**req.view_args)
  File "/Users/davemagarian/PycharmProjects/Meme-Flask/app/views.py", line 126, in upldfile
    x = mpimg.imread(file_stream)
  File "/Users/davemagarian/PycharmProjects/Meme-Flask/venv/lib/python3.7/site-packages/matplotlib/image.py", line 1436, in imread
    return handler(fname)
  File "/Users/davemagarian/PycharmProjects/Meme-Flask/venv/lib/python3.7/site-packages/matplotlib/image.py", line 1390, in read_png
    return _png.read_png(*args, **kwargs)
OSError: read past end of file
[2019-10-26 12:52:52] ERROR    Exception on /uploadajax [POST]
Traceback (most recent call last):
  File "/Users/davemagarian/PycharmProjects/Meme-Flask/venv/lib/python3.7/site-packages/flask/app.py", line 2446, in wsgi_app
    response = self.full_dispatch_request()
  File "/Users/davemagarian/PycharmProjects/Meme-Flask/venv/lib/python3.7/site-packages/flask/app.py", line 1951, in full_dispatch_request
    rv = self.handle_user_exception(e)
  File "/Users/davemagarian/PycharmProjects/Meme-Flask/venv/lib/python3.7/site-packages/flask/app.py", line 1820, in handle_user_exception
    reraise(exc_type, exc_value, tb)
  File "/Users/davemagarian/PycharmProjects/Meme-Flask/venv/lib/python3.7/site-packages/flask/_compat.py", line 39, in reraise
    raise value
  File "/Users/davemagarian/PycharmProjects/Meme-Flask/venv/lib/python3.7/site-packages/flask/app.py", line 1949, in full_dispatch_request
    rv = self.dispatch_request()
  File "/Users/davemagarian/PycharmProjects/Meme-Flask/venv/lib/python3.7/site-packages/flask/app.py", line 1935, in dispatch_request
    return self.view_functions[rule.endpoint](**req.view_args)
  File "/Users/davemagarian/PycharmProjects/Meme-Flask/app/views.py", line 126, in upldfile
    x = mpimg.imread(file_stream)
  File "/Users/davemagarian/PycharmProjects/Meme-Flask/venv/lib/python3.7/site-packages/matplotlib/image.py", line 1436, in imread
    return handler(fname)
  File "/Users/davemagarian/PycharmProjects/Meme-Flask/venv/lib/python3.7/site-packages/matplotlib/image.py", line 1390, in read_png
    return _png.read_png(*args, **kwargs)
OSError: read past end of file
[2019-10-26 12:54:21] ERROR    Exception on /uploadajax [POST]
Traceback (most recent call last):
  File "/Users/davemagarian/PycharmProjects/Meme-Flask/venv/lib/python3.7/site-packages/flask/app.py", line 2446, in wsgi_app
    response = self.full_dispatch_request()
  File "/Users/davemagarian/PycharmProjects/Meme-Flask/venv/lib/python3.7/site-packages/flask/app.py", line 1951, in full_dispatch_request
    rv = self.handle_user_exception(e)
  File "/Users/davemagarian/PycharmProjects/Meme-Flask/venv/lib/python3.7/site-packages/flask/app.py", line 1820, in handle_user_exception
    reraise(exc_type, exc_value, tb)
  File "/Users/davemagarian/PycharmProjects/Meme-Flask/venv/lib/python3.7/site-packages/flask/_compat.py", line 39, in reraise
    raise value
  File "/Users/davemagarian/PycharmProjects/Meme-Flask/venv/lib/python3.7/site-packages/flask/app.py", line 1949, in full_dispatch_request
    rv = self.dispatch_request()
  File "/Users/davemagarian/PycharmProjects/Meme-Flask/venv/lib/python3.7/site-packages/flask/app.py", line 1935, in dispatch_request
    return self.view_functions[rule.endpoint](**req.view_args)
  File "/Users/davemagarian/PycharmProjects/Meme-Flask/app/views.py", line 126, in upldfile
    x = mpimg.imread(file_stream)
  File "/Users/davemagarian/PycharmProjects/Meme-Flask/venv/lib/python3.7/site-packages/matplotlib/image.py", line 1436, in imread
    return handler(fname)
  File "/Users/davemagarian/PycharmProjects/Meme-Flask/venv/lib/python3.7/site-packages/matplotlib/image.py", line 1390, in read_png
    return _png.read_png(*args, **kwargs)
OSError: read past end of file
[2019-10-26 17:25:16] ERROR    Exception on /uploadajax [POST]
Traceback (most recent call last):
  File "/Users/davemagarian/PycharmProjects/Meme-Flask/venv/lib/python3.7/site-packages/flask/app.py", line 2446, in wsgi_app
    response = self.full_dispatch_request()
  File "/Users/davemagarian/PycharmProjects/Meme-Flask/venv/lib/python3.7/site-packages/flask/app.py", line 1951, in full_dispatch_request
    rv = self.handle_user_exception(e)
  File "/Users/davemagarian/PycharmProjects/Meme-Flask/venv/lib/python3.7/site-packages/flask/app.py", line 1820, in handle_user_exception
    reraise(exc_type, exc_value, tb)
  File "/Users/davemagarian/PycharmProjects/Meme-Flask/venv/lib/python3.7/site-packages/flask/_compat.py", line 39, in reraise
    raise value
  File "/Users/davemagarian/PycharmProjects/Meme-Flask/venv/lib/python3.7/site-packages/flask/app.py", line 1949, in full_dispatch_request
    rv = self.dispatch_request()
  File "/Users/davemagarian/PycharmProjects/Meme-Flask/venv/lib/python3.7/site-packages/flask/app.py", line 1935, in dispatch_request
    return self.view_functions[rule.endpoint](**req.view_args)
  File "/Users/davemagarian/PycharmProjects/Meme-Flask/app/views.py", line 127, in upldfile
    x = mpimg.imread(file_stream)
  File "/Users/davemagarian/PycharmProjects/Meme-Flask/venv/lib/python3.7/site-packages/matplotlib/image.py", line 1436, in imread
    return handler(fname)
  File "/Users/davemagarian/PycharmProjects/Meme-Flask/venv/lib/python3.7/site-packages/matplotlib/image.py", line 1390, in read_png
    return _png.read_png(*args, **kwargs)
OSError: read past end of file
[2019-10-27 07:05:21] ERROR    Exception on /uploadajax [POST]
Traceback (most recent call last):
  File "/Users/davemagarian/PycharmProjects/Meme-Flask/venv/lib/python3.7/site-packages/flask/app.py", line 2446, in wsgi_app
    response = self.full_dispatch_request()
  File "/Users/davemagarian/PycharmProjects/Meme-Flask/venv/lib/python3.7/site-packages/flask/app.py", line 1951, in full_dispatch_request
    rv = self.handle_user_exception(e)
  File "/Users/davemagarian/PycharmProjects/Meme-Flask/venv/lib/python3.7/site-packages/flask/app.py", line 1820, in handle_user_exception
    reraise(exc_type, exc_value, tb)
  File "/Users/davemagarian/PycharmProjects/Meme-Flask/venv/lib/python3.7/site-packages/flask/_compat.py", line 39, in reraise
    raise value
  File "/Users/davemagarian/PycharmProjects/Meme-Flask/venv/lib/python3.7/site-packages/flask/app.py", line 1949, in full_dispatch_request
    rv = self.dispatch_request()
  File "/Users/davemagarian/PycharmProjects/Meme-Flask/venv/lib/python3.7/site-packages/flask/app.py", line 1935, in dispatch_request
    return self.view_functions[rule.endpoint](**req.view_args)
  File "/Users/davemagarian/PycharmProjects/Meme-Flask/app/views.py", line 126, in upldfile
    file_stream = io.StringIO(files.read())
TypeError: initial_value must be str or None, not bytes
[2019-10-27 07:06:13] ERROR    Exception on /uploadajax [POST]
Traceback (most recent call last):
  File "/Users/davemagarian/PycharmProjects/Meme-Flask/venv/lib/python3.7/site-packages/flask/app.py", line 2446, in wsgi_app
    response = self.full_dispatch_request()
  File "/Users/davemagarian/PycharmProjects/Meme-Flask/venv/lib/python3.7/site-packages/flask/app.py", line 1951, in full_dispatch_request
    rv = self.handle_user_exception(e)
  File "/Users/davemagarian/PycharmProjects/Meme-Flask/venv/lib/python3.7/site-packages/flask/app.py", line 1820, in handle_user_exception
    reraise(exc_type, exc_value, tb)
  File "/Users/davemagarian/PycharmProjects/Meme-Flask/venv/lib/python3.7/site-packages/flask/_compat.py", line 39, in reraise
    raise value
  File "/Users/davemagarian/PycharmProjects/Meme-Flask/venv/lib/python3.7/site-packages/flask/app.py", line 1949, in full_dispatch_request
    rv = self.dispatch_request()
  File "/Users/davemagarian/PycharmProjects/Meme-Flask/venv/lib/python3.7/site-packages/flask/app.py", line 1935, in dispatch_request
    return self.view_functions[rule.endpoint](**req.view_args)
  File "/Users/davemagarian/PycharmProjects/Meme-Flask/app/views.py", line 184, in upldfile
    my_bucket.Object(combined).put(Body=filename)
  File "/Users/davemagarian/PycharmProjects/Meme-Flask/venv/lib/python3.7/site-packages/boto3/resources/factory.py", line 520, in do_action
    response = action(self, *args, **kwargs)
  File "/Users/davemagarian/PycharmProjects/Meme-Flask/venv/lib/python3.7/site-packages/boto3/resources/action.py", line 83, in __call__
    response = getattr(parent.meta.client, operation_name)(**params)
  File "/Users/davemagarian/PycharmProjects/Meme-Flask/venv/lib/python3.7/site-packages/botocore/client.py", line 357, in _api_call
    return self._make_api_call(operation_name, kwargs)
  File "/Users/davemagarian/PycharmProjects/Meme-Flask/venv/lib/python3.7/site-packages/botocore/client.py", line 634, in _make_api_call
    api_params, operation_model, context=request_context)
  File "/Users/davemagarian/PycharmProjects/Meme-Flask/venv/lib/python3.7/site-packages/botocore/client.py", line 682, in _convert_to_request_dict
    api_params, operation_model)
  File "/Users/davemagarian/PycharmProjects/Meme-Flask/venv/lib/python3.7/site-packages/botocore/validate.py", line 297, in serialize_to_request
    raise ParamValidationError(report=report.generate_report())
botocore.exceptions.ParamValidationError: Parameter validation failed:
Invalid type for parameter Key, value: <PIL.Image.Image image mode=RGBA size=1280x1252 at 0x118D87E48>, type: <class 'PIL.Image.Image'>, valid types: <class 'str'>
[2019-10-27 07:06:46] ERROR    Exception on /uploadajax [POST]
Traceback (most recent call last):
  File "/Users/davemagarian/PycharmProjects/Meme-Flask/venv/lib/python3.7/site-packages/flask/app.py", line 2446, in wsgi_app
    response = self.full_dispatch_request()
  File "/Users/davemagarian/PycharmProjects/Meme-Flask/venv/lib/python3.7/site-packages/flask/app.py", line 1951, in full_dispatch_request
    rv = self.handle_user_exception(e)
  File "/Users/davemagarian/PycharmProjects/Meme-Flask/venv/lib/python3.7/site-packages/flask/app.py", line 1820, in handle_user_exception
    reraise(exc_type, exc_value, tb)
  File "/Users/davemagarian/PycharmProjects/Meme-Flask/venv/lib/python3.7/site-packages/flask/_compat.py", line 39, in reraise
    raise value
  File "/Users/davemagarian/PycharmProjects/Meme-Flask/venv/lib/python3.7/site-packages/flask/app.py", line 1949, in full_dispatch_request
    rv = self.dispatch_request()
  File "/Users/davemagarian/PycharmProjects/Meme-Flask/venv/lib/python3.7/site-packages/flask/app.py", line 1935, in dispatch_request
    return self.view_functions[rule.endpoint](**req.view_args)
  File "/Users/davemagarian/PycharmProjects/Meme-Flask/app/views.py", line 184, in upldfile
    my_bucket.Object(combined).put(Body=filename)
  File "/Users/davemagarian/PycharmProjects/Meme-Flask/venv/lib/python3.7/site-packages/boto3/resources/factory.py", line 520, in do_action
    response = action(self, *args, **kwargs)
  File "/Users/davemagarian/PycharmProjects/Meme-Flask/venv/lib/python3.7/site-packages/boto3/resources/action.py", line 83, in __call__
    response = getattr(parent.meta.client, operation_name)(**params)
  File "/Users/davemagarian/PycharmProjects/Meme-Flask/venv/lib/python3.7/site-packages/botocore/client.py", line 357, in _api_call
    return self._make_api_call(operation_name, kwargs)
  File "/Users/davemagarian/PycharmProjects/Meme-Flask/venv/lib/python3.7/site-packages/botocore/client.py", line 634, in _make_api_call
    api_params, operation_model, context=request_context)
  File "/Users/davemagarian/PycharmProjects/Meme-Flask/venv/lib/python3.7/site-packages/botocore/client.py", line 682, in _convert_to_request_dict
    api_params, operation_model)
  File "/Users/davemagarian/PycharmProjects/Meme-Flask/venv/lib/python3.7/site-packages/botocore/validate.py", line 297, in serialize_to_request
    raise ParamValidationError(report=report.generate_report())
botocore.exceptions.ParamValidationError: Parameter validation failed:
Invalid type for parameter Key, value: <PIL.Image.Image image mode=RGBA size=1280x3544 at 0x111D9CB70>, type: <class 'PIL.Image.Image'>, valid types: <class 'str'>
[2019-10-27 07:07:03] ERROR    Exception on /uploadajax [POST]
Traceback (most recent call last):
  File "/Users/davemagarian/PycharmProjects/Meme-Flask/venv/lib/python3.7/site-packages/flask/app.py", line 2446, in wsgi_app
    response = self.full_dispatch_request()
  File "/Users/davemagarian/PycharmProjects/Meme-Flask/venv/lib/python3.7/site-packages/flask/app.py", line 1951, in full_dispatch_request
    rv = self.handle_user_exception(e)
  File "/Users/davemagarian/PycharmProjects/Meme-Flask/venv/lib/python3.7/site-packages/flask/app.py", line 1820, in handle_user_exception
    reraise(exc_type, exc_value, tb)
  File "/Users/davemagarian/PycharmProjects/Meme-Flask/venv/lib/python3.7/site-packages/flask/_compat.py", line 39, in reraise
    raise value
  File "/Users/davemagarian/PycharmProjects/Meme-Flask/venv/lib/python3.7/site-packages/flask/app.py", line 1949, in full_dispatch_request
    rv = self.dispatch_request()
  File "/Users/davemagarian/PycharmProjects/Meme-Flask/venv/lib/python3.7/site-packages/flask/app.py", line 1935, in dispatch_request
    return self.view_functions[rule.endpoint](**req.view_args)
  File "/Users/davemagarian/PycharmProjects/Meme-Flask/app/views.py", line 184, in upldfile
    my_bucket.Object(combined).put(Body=filename)
NameError: name 'my_bucket' is not defined
[2019-10-27 07:08:39] ERROR    Exception on /uploadajax [POST]
Traceback (most recent call last):
  File "/Users/davemagarian/PycharmProjects/Meme-Flask/venv/lib/python3.7/site-packages/flask/app.py", line 2446, in wsgi_app
    response = self.full_dispatch_request()
  File "/Users/davemagarian/PycharmProjects/Meme-Flask/venv/lib/python3.7/site-packages/flask/app.py", line 1951, in full_dispatch_request
    rv = self.handle_user_exception(e)
  File "/Users/davemagarian/PycharmProjects/Meme-Flask/venv/lib/python3.7/site-packages/flask/app.py", line 1820, in handle_user_exception
    reraise(exc_type, exc_value, tb)
  File "/Users/davemagarian/PycharmProjects/Meme-Flask/venv/lib/python3.7/site-packages/flask/_compat.py", line 39, in reraise
    raise value
  File "/Users/davemagarian/PycharmProjects/Meme-Flask/venv/lib/python3.7/site-packages/flask/app.py", line 1949, in full_dispatch_request
    rv = self.dispatch_request()
  File "/Users/davemagarian/PycharmProjects/Meme-Flask/venv/lib/python3.7/site-packages/flask/app.py", line 1935, in dispatch_request
    return self.view_functions[rule.endpoint](**req.view_args)
  File "/Users/davemagarian/PycharmProjects/Meme-Flask/app/views.py", line 187, in upldfile
    my_bucket.Object(combined).put(Body=filename)
  File "/Users/davemagarian/PycharmProjects/Meme-Flask/venv/lib/python3.7/site-packages/boto3/resources/factory.py", line 520, in do_action
    response = action(self, *args, **kwargs)
  File "/Users/davemagarian/PycharmProjects/Meme-Flask/venv/lib/python3.7/site-packages/boto3/resources/action.py", line 83, in __call__
    response = getattr(parent.meta.client, operation_name)(**params)
  File "/Users/davemagarian/PycharmProjects/Meme-Flask/venv/lib/python3.7/site-packages/botocore/client.py", line 357, in _api_call
    return self._make_api_call(operation_name, kwargs)
  File "/Users/davemagarian/PycharmProjects/Meme-Flask/venv/lib/python3.7/site-packages/botocore/client.py", line 634, in _make_api_call
    api_params, operation_model, context=request_context)
  File "/Users/davemagarian/PycharmProjects/Meme-Flask/venv/lib/python3.7/site-packages/botocore/client.py", line 682, in _convert_to_request_dict
    api_params, operation_model)
  File "/Users/davemagarian/PycharmProjects/Meme-Flask/venv/lib/python3.7/site-packages/botocore/validate.py", line 297, in serialize_to_request
    raise ParamValidationError(report=report.generate_report())
botocore.exceptions.ParamValidationError: Parameter validation failed:
Invalid type for parameter Key, value: <PIL.Image.Image image mode=RGBA size=1280x1252 at 0x11DB82080>, type: <class 'PIL.Image.Image'>, valid types: <class 'str'>
[2019-10-27 07:10:32] ERROR    Exception on /uploadajax [POST]
Traceback (most recent call last):
  File "/Users/davemagarian/PycharmProjects/Meme-Flask/venv/lib/python3.7/site-packages/flask/app.py", line 2446, in wsgi_app
    response = self.full_dispatch_request()
  File "/Users/davemagarian/PycharmProjects/Meme-Flask/venv/lib/python3.7/site-packages/flask/app.py", line 1951, in full_dispatch_request
    rv = self.handle_user_exception(e)
  File "/Users/davemagarian/PycharmProjects/Meme-Flask/venv/lib/python3.7/site-packages/flask/app.py", line 1820, in handle_user_exception
    reraise(exc_type, exc_value, tb)
  File "/Users/davemagarian/PycharmProjects/Meme-Flask/venv/lib/python3.7/site-packages/flask/_compat.py", line 39, in reraise
    raise value
  File "/Users/davemagarian/PycharmProjects/Meme-Flask/venv/lib/python3.7/site-packages/flask/app.py", line 1949, in full_dispatch_request
    rv = self.dispatch_request()
  File "/Users/davemagarian/PycharmProjects/Meme-Flask/venv/lib/python3.7/site-packages/flask/app.py", line 1935, in dispatch_request
    return self.view_functions[rule.endpoint](**req.view_args)
  File "/Users/davemagarian/PycharmProjects/Meme-Flask/app/views.py", line 187, in upldfile
    my_bucket.Object(combined).put(Body=filename)
  File "/Users/davemagarian/PycharmProjects/Meme-Flask/venv/lib/python3.7/site-packages/boto3/resources/factory.py", line 520, in do_action
    response = action(self, *args, **kwargs)
  File "/Users/davemagarian/PycharmProjects/Meme-Flask/venv/lib/python3.7/site-packages/boto3/resources/action.py", line 83, in __call__
    response = getattr(parent.meta.client, operation_name)(**params)
  File "/Users/davemagarian/PycharmProjects/Meme-Flask/venv/lib/python3.7/site-packages/botocore/client.py", line 357, in _api_call
    return self._make_api_call(operation_name, kwargs)
  File "/Users/davemagarian/PycharmProjects/Meme-Flask/venv/lib/python3.7/site-packages/botocore/client.py", line 634, in _make_api_call
    api_params, operation_model, context=request_context)
  File "/Users/davemagarian/PycharmProjects/Meme-Flask/venv/lib/python3.7/site-packages/botocore/client.py", line 682, in _convert_to_request_dict
    api_params, operation_model)
  File "/Users/davemagarian/PycharmProjects/Meme-Flask/venv/lib/python3.7/site-packages/botocore/validate.py", line 297, in serialize_to_request
    raise ParamValidationError(report=report.generate_report())
botocore.exceptions.ParamValidationError: Parameter validation failed:
Invalid type for parameter Key, value: <PIL.Image.Image image mode=RGBA size=1280x1252 at 0x1126E6208>, type: <class 'PIL.Image.Image'>, valid types: <class 'str'>
[2019-10-27 07:10:51] ERROR    Exception on /uploadajax [POST]
Traceback (most recent call last):
  File "/Users/davemagarian/PycharmProjects/Meme-Flask/venv/lib/python3.7/site-packages/flask/app.py", line 2446, in wsgi_app
    response = self.full_dispatch_request()
  File "/Users/davemagarian/PycharmProjects/Meme-Flask/venv/lib/python3.7/site-packages/flask/app.py", line 1951, in full_dispatch_request
    rv = self.handle_user_exception(e)
  File "/Users/davemagarian/PycharmProjects/Meme-Flask/venv/lib/python3.7/site-packages/flask/app.py", line 1820, in handle_user_exception
    reraise(exc_type, exc_value, tb)
  File "/Users/davemagarian/PycharmProjects/Meme-Flask/venv/lib/python3.7/site-packages/flask/_compat.py", line 39, in reraise
    raise value
  File "/Users/davemagarian/PycharmProjects/Meme-Flask/venv/lib/python3.7/site-packages/flask/app.py", line 1949, in full_dispatch_request
    rv = self.dispatch_request()
  File "/Users/davemagarian/PycharmProjects/Meme-Flask/venv/lib/python3.7/site-packages/flask/app.py", line 1935, in dispatch_request
    return self.view_functions[rule.endpoint](**req.view_args)
  File "/Users/davemagarian/PycharmProjects/Meme-Flask/app/views.py", line 187, in upldfile
    my_bucket.Object(combined).put(Body=filename)
  File "/Users/davemagarian/PycharmProjects/Meme-Flask/venv/lib/python3.7/site-packages/boto3/resources/factory.py", line 520, in do_action
    response = action(self, *args, **kwargs)
  File "/Users/davemagarian/PycharmProjects/Meme-Flask/venv/lib/python3.7/site-packages/boto3/resources/action.py", line 83, in __call__
    response = getattr(parent.meta.client, operation_name)(**params)
  File "/Users/davemagarian/PycharmProjects/Meme-Flask/venv/lib/python3.7/site-packages/botocore/client.py", line 357, in _api_call
    return self._make_api_call(operation_name, kwargs)
  File "/Users/davemagarian/PycharmProjects/Meme-Flask/venv/lib/python3.7/site-packages/botocore/client.py", line 634, in _make_api_call
    api_params, operation_model, context=request_context)
  File "/Users/davemagarian/PycharmProjects/Meme-Flask/venv/lib/python3.7/site-packages/botocore/client.py", line 682, in _convert_to_request_dict
    api_params, operation_model)
  File "/Users/davemagarian/PycharmProjects/Meme-Flask/venv/lib/python3.7/site-packages/botocore/validate.py", line 297, in serialize_to_request
    raise ParamValidationError(report=report.generate_report())
botocore.exceptions.ParamValidationError: Parameter validation failed:
Invalid type for parameter Key, value: <PIL.Image.Image image mode=RGBA size=1280x1252 at 0x114C10CC0>, type: <class 'PIL.Image.Image'>, valid types: <class 'str'>
[2019-10-27 07:12:27] ERROR    Exception on /uploadajax [POST]
Traceback (most recent call last):
  File "/Users/davemagarian/PycharmProjects/Meme-Flask/venv/lib/python3.7/site-packages/flask/app.py", line 2446, in wsgi_app
    response = self.full_dispatch_request()
  File "/Users/davemagarian/PycharmProjects/Meme-Flask/venv/lib/python3.7/site-packages/flask/app.py", line 1951, in full_dispatch_request
    rv = self.handle_user_exception(e)
  File "/Users/davemagarian/PycharmProjects/Meme-Flask/venv/lib/python3.7/site-packages/flask/app.py", line 1820, in handle_user_exception
    reraise(exc_type, exc_value, tb)
  File "/Users/davemagarian/PycharmProjects/Meme-Flask/venv/lib/python3.7/site-packages/flask/_compat.py", line 39, in reraise
    raise value
  File "/Users/davemagarian/PycharmProjects/Meme-Flask/venv/lib/python3.7/site-packages/flask/app.py", line 1949, in full_dispatch_request
    rv = self.dispatch_request()
  File "/Users/davemagarian/PycharmProjects/Meme-Flask/venv/lib/python3.7/site-packages/flask/app.py", line 1935, in dispatch_request
    return self.view_functions[rule.endpoint](**req.view_args)
  File "/Users/davemagarian/PycharmProjects/Meme-Flask/app/views.py", line 187, in upldfile
  File "/Users/davemagarian/PycharmProjects/Meme-Flask/venv/lib/python3.7/site-packages/boto3/resources/factory.py", line 520, in do_action
    response = action(self, *args, **kwargs)
  File "/Users/davemagarian/PycharmProjects/Meme-Flask/venv/lib/python3.7/site-packages/boto3/resources/action.py", line 83, in __call__
    response = getattr(parent.meta.client, operation_name)(**params)
  File "/Users/davemagarian/PycharmProjects/Meme-Flask/venv/lib/python3.7/site-packages/botocore/client.py", line 357, in _api_call
    return self._make_api_call(operation_name, kwargs)
  File "/Users/davemagarian/PycharmProjects/Meme-Flask/venv/lib/python3.7/site-packages/botocore/client.py", line 634, in _make_api_call
    api_params, operation_model, context=request_context)
  File "/Users/davemagarian/PycharmProjects/Meme-Flask/venv/lib/python3.7/site-packages/botocore/client.py", line 682, in _convert_to_request_dict
    api_params, operation_model)
  File "/Users/davemagarian/PycharmProjects/Meme-Flask/venv/lib/python3.7/site-packages/botocore/validate.py", line 297, in serialize_to_request
    raise ParamValidationError(report=report.generate_report())
botocore.exceptions.ParamValidationError: Parameter validation failed:
Invalid type for parameter Key, value: <PIL.Image.Image image mode=RGBA size=1280x1252 at 0x113CE39E8>, type: <class 'PIL.Image.Image'>, valid types: <class 'str'>
[2019-10-27 07:13:40] ERROR    Exception on /uploadajax [POST]
Traceback (most recent call last):
  File "/Users/davemagarian/PycharmProjects/Meme-Flask/venv/lib/python3.7/site-packages/flask/app.py", line 2446, in wsgi_app
    response = self.full_dispatch_request()
  File "/Users/davemagarian/PycharmProjects/Meme-Flask/venv/lib/python3.7/site-packages/flask/app.py", line 1952, in full_dispatch_request
    return self.finalize_request(rv)
  File "/Users/davemagarian/PycharmProjects/Meme-Flask/venv/lib/python3.7/site-packages/flask/app.py", line 1967, in finalize_request
    response = self.make_response(rv)
  File "/Users/davemagarian/PycharmProjects/Meme-Flask/venv/lib/python3.7/site-packages/flask/app.py", line 2097, in make_response
    "The view function did not return a valid response. The"
TypeError: The view function did not return a valid response. The function either returned None or ended without a return statement.
[2019-10-27 07:13:52] ERROR    Exception on /uploadajax [POST]
Traceback (most recent call last):
  File "/Users/davemagarian/PycharmProjects/Meme-Flask/venv/lib/python3.7/site-packages/flask/app.py", line 2446, in wsgi_app
    response = self.full_dispatch_request()
  File "/Users/davemagarian/PycharmProjects/Meme-Flask/venv/lib/python3.7/site-packages/flask/app.py", line 1952, in full_dispatch_request
    return self.finalize_request(rv)
  File "/Users/davemagarian/PycharmProjects/Meme-Flask/venv/lib/python3.7/site-packages/flask/app.py", line 1967, in finalize_request
    response = self.make_response(rv)
  File "/Users/davemagarian/PycharmProjects/Meme-Flask/venv/lib/python3.7/site-packages/flask/app.py", line 2097, in make_response
    "The view function did not return a valid response. The"
TypeError: The view function did not return a valid response. The function either returned None or ended without a return statement.
[2019-10-27 07:19:10] ERROR    Exception on /uploadajax [POST]
Traceback (most recent call last):
  File "/Users/davemagarian/PycharmProjects/Meme-Flask/venv/lib/python3.7/site-packages/flask/app.py", line 2446, in wsgi_app
    response = self.full_dispatch_request()
  File "/Users/davemagarian/PycharmProjects/Meme-Flask/venv/lib/python3.7/site-packages/flask/app.py", line 1952, in full_dispatch_request
    return self.finalize_request(rv)
  File "/Users/davemagarian/PycharmProjects/Meme-Flask/venv/lib/python3.7/site-packages/flask/app.py", line 1967, in finalize_request
    response = self.make_response(rv)
  File "/Users/davemagarian/PycharmProjects/Meme-Flask/venv/lib/python3.7/site-packages/flask/app.py", line 2097, in make_response
    "The view function did not return a valid response. The"
TypeError: The view function did not return a valid response. The function either returned None or ended without a return statement.
[2019-10-27 07:45:58] ERROR    Exception on /uploadajax [POST]
Traceback (most recent call last):
  File "/Users/davemagarian/PycharmProjects/Meme-Flask/venv/lib/python3.7/site-packages/flask/app.py", line 2446, in wsgi_app
    response = self.full_dispatch_request()
  File "/Users/davemagarian/PycharmProjects/Meme-Flask/venv/lib/python3.7/site-packages/flask/app.py", line 1952, in full_dispatch_request
    return self.finalize_request(rv)
  File "/Users/davemagarian/PycharmProjects/Meme-Flask/venv/lib/python3.7/site-packages/flask/app.py", line 1967, in finalize_request
    response = self.make_response(rv)
  File "/Users/davemagarian/PycharmProjects/Meme-Flask/venv/lib/python3.7/site-packages/flask/app.py", line 2097, in make_response
    "The view function did not return a valid response. The"
TypeError: The view function did not return a valid response. The function either returned None or ended without a return statement.
[2019-10-27 07:50:04] ERROR    Exception on /uploadajax [POST]
Traceback (most recent call last):
  File "/Users/davemagarian/PycharmProjects/Meme-Flask/venv/lib/python3.7/site-packages/flask/app.py", line 2446, in wsgi_app
    response = self.full_dispatch_request()
  File "/Users/davemagarian/PycharmProjects/Meme-Flask/venv/lib/python3.7/site-packages/flask/app.py", line 1951, in full_dispatch_request
    rv = self.handle_user_exception(e)
  File "/Users/davemagarian/PycharmProjects/Meme-Flask/venv/lib/python3.7/site-packages/flask/app.py", line 1820, in handle_user_exception
    reraise(exc_type, exc_value, tb)
  File "/Users/davemagarian/PycharmProjects/Meme-Flask/venv/lib/python3.7/site-packages/flask/_compat.py", line 39, in reraise
    raise value
  File "/Users/davemagarian/PycharmProjects/Meme-Flask/venv/lib/python3.7/site-packages/flask/app.py", line 1949, in full_dispatch_request
    rv = self.dispatch_request()
  File "/Users/davemagarian/PycharmProjects/Meme-Flask/venv/lib/python3.7/site-packages/flask/app.py", line 1935, in dispatch_request
    return self.view_functions[rule.endpoint](**req.view_args)
  File "/Users/davemagarian/PycharmProjects/Meme-Flask/app/views.py", line 184, in upldfile
    newcombined = combined.read()
AttributeError: 'Image' object has no attribute 'read'
[2019-10-27 07:51:05] ERROR    Exception on /uploadajax [POST]
Traceback (most recent call last):
  File "/Users/davemagarian/PycharmProjects/Meme-Flask/venv/lib/python3.7/site-packages/flask/app.py", line 2446, in wsgi_app
    response = self.full_dispatch_request()
  File "/Users/davemagarian/PycharmProjects/Meme-Flask/venv/lib/python3.7/site-packages/flask/app.py", line 1951, in full_dispatch_request
    rv = self.handle_user_exception(e)
  File "/Users/davemagarian/PycharmProjects/Meme-Flask/venv/lib/python3.7/site-packages/flask/app.py", line 1820, in handle_user_exception
    reraise(exc_type, exc_value, tb)
  File "/Users/davemagarian/PycharmProjects/Meme-Flask/venv/lib/python3.7/site-packages/flask/_compat.py", line 39, in reraise
    raise value
  File "/Users/davemagarian/PycharmProjects/Meme-Flask/venv/lib/python3.7/site-packages/flask/app.py", line 1949, in full_dispatch_request
    rv = self.dispatch_request()
  File "/Users/davemagarian/PycharmProjects/Meme-Flask/venv/lib/python3.7/site-packages/flask/app.py", line 1935, in dispatch_request
    return self.view_functions[rule.endpoint](**req.view_args)
  File "/Users/davemagarian/PycharmProjects/Meme-Flask/app/views.py", line 190, in upldfile
    my_bucket.Object(filename).put(Body=combined)
  File "/Users/davemagarian/PycharmProjects/Meme-Flask/venv/lib/python3.7/site-packages/boto3/resources/factory.py", line 520, in do_action
    response = action(self, *args, **kwargs)
  File "/Users/davemagarian/PycharmProjects/Meme-Flask/venv/lib/python3.7/site-packages/boto3/resources/action.py", line 83, in __call__
    response = getattr(parent.meta.client, operation_name)(**params)
  File "/Users/davemagarian/PycharmProjects/Meme-Flask/venv/lib/python3.7/site-packages/botocore/client.py", line 357, in _api_call
    return self._make_api_call(operation_name, kwargs)
  File "/Users/davemagarian/PycharmProjects/Meme-Flask/venv/lib/python3.7/site-packages/botocore/client.py", line 634, in _make_api_call
    api_params, operation_model, context=request_context)
  File "/Users/davemagarian/PycharmProjects/Meme-Flask/venv/lib/python3.7/site-packages/botocore/client.py", line 682, in _convert_to_request_dict
    api_params, operation_model)
  File "/Users/davemagarian/PycharmProjects/Meme-Flask/venv/lib/python3.7/site-packages/botocore/validate.py", line 297, in serialize_to_request
    raise ParamValidationError(report=report.generate_report())
botocore.exceptions.ParamValidationError: Parameter validation failed:
Invalid type for parameter Body, value: <PIL.Image.Image image mode=RGBA size=1280x1252 at 0x11D216320>, type: <class 'PIL.Image.Image'>, valid types: <class 'bytes'>, <class 'bytearray'>, file-like object
[2019-10-27 07:55:07] ERROR    Exception on /uploadajax [POST]
Traceback (most recent call last):
  File "/Users/davemagarian/PycharmProjects/Meme-Flask/venv/lib/python3.7/site-packages/flask/app.py", line 2446, in wsgi_app
    response = self.full_dispatch_request()
  File "/Users/davemagarian/PycharmProjects/Meme-Flask/venv/lib/python3.7/site-packages/flask/app.py", line 1951, in full_dispatch_request
    rv = self.handle_user_exception(e)
  File "/Users/davemagarian/PycharmProjects/Meme-Flask/venv/lib/python3.7/site-packages/flask/app.py", line 1820, in handle_user_exception
    reraise(exc_type, exc_value, tb)
  File "/Users/davemagarian/PycharmProjects/Meme-Flask/venv/lib/python3.7/site-packages/flask/_compat.py", line 39, in reraise
    raise value
  File "/Users/davemagarian/PycharmProjects/Meme-Flask/venv/lib/python3.7/site-packages/flask/app.py", line 1949, in full_dispatch_request
    rv = self.dispatch_request()
  File "/Users/davemagarian/PycharmProjects/Meme-Flask/venv/lib/python3.7/site-packages/flask/app.py", line 1935, in dispatch_request
    return self.view_functions[rule.endpoint](**req.view_args)
  File "/Users/davemagarian/PycharmProjects/Meme-Flask/app/views.py", line 190, in upldfile
    my_bucket.Object(filename).put(Body=combined.read())
AttributeError: 'Image' object has no attribute 'read'
[2019-10-27 07:55:25] ERROR    Exception on /uploadajax [POST]
Traceback (most recent call last):
  File "/Users/davemagarian/PycharmProjects/Meme-Flask/venv/lib/python3.7/site-packages/flask/app.py", line 2446, in wsgi_app
    response = self.full_dispatch_request()
  File "/Users/davemagarian/PycharmProjects/Meme-Flask/venv/lib/python3.7/site-packages/flask/app.py", line 1951, in full_dispatch_request
    rv = self.handle_user_exception(e)
  File "/Users/davemagarian/PycharmProjects/Meme-Flask/venv/lib/python3.7/site-packages/flask/app.py", line 1820, in handle_user_exception
    reraise(exc_type, exc_value, tb)
  File "/Users/davemagarian/PycharmProjects/Meme-Flask/venv/lib/python3.7/site-packages/flask/_compat.py", line 39, in reraise
    raise value
  File "/Users/davemagarian/PycharmProjects/Meme-Flask/venv/lib/python3.7/site-packages/flask/app.py", line 1949, in full_dispatch_request
    rv = self.dispatch_request()
  File "/Users/davemagarian/PycharmProjects/Meme-Flask/venv/lib/python3.7/site-packages/flask/app.py", line 1935, in dispatch_request
    return self.view_functions[rule.endpoint](**req.view_args)
  File "/Users/davemagarian/PycharmProjects/Meme-Flask/app/views.py", line 190, in upldfile
    my_bucket.Object(filename).put(Body=combined)
AttributeError: 'Image' object has no attribute 'read'
[2019-10-27 07:55:57] ERROR    Exception on /uploadajax [POST]
Traceback (most recent call last):
  File "/Users/davemagarian/PycharmProjects/Meme-Flask/venv/lib/python3.7/site-packages/flask/app.py", line 2446, in wsgi_app
    response = self.full_dispatch_request()
  File "/Users/davemagarian/PycharmProjects/Meme-Flask/venv/lib/python3.7/site-packages/flask/app.py", line 1952, in full_dispatch_request
    return self.finalize_request(rv)
  File "/Users/davemagarian/PycharmProjects/Meme-Flask/venv/lib/python3.7/site-packages/flask/app.py", line 1967, in finalize_request
    response = self.make_response(rv)
  File "/Users/davemagarian/PycharmProjects/Meme-Flask/venv/lib/python3.7/site-packages/flask/app.py", line 2097, in make_response
    "The view function did not return a valid response. The"
TypeError: The view function did not return a valid response. The function either returned None or ended without a return statement.
[2019-10-27 07:59:22] ERROR    Exception on /uploadajax [POST]
Traceback (most recent call last):
  File "/Users/davemagarian/PycharmProjects/Meme-Flask/venv/lib/python3.7/site-packages/flask/app.py", line 2446, in wsgi_app
    response = self.full_dispatch_request()
  File "/Users/davemagarian/PycharmProjects/Meme-Flask/venv/lib/python3.7/site-packages/flask/app.py", line 1951, in full_dispatch_request
    rv = self.handle_user_exception(e)
  File "/Users/davemagarian/PycharmProjects/Meme-Flask/venv/lib/python3.7/site-packages/flask/app.py", line 1820, in handle_user_exception
    reraise(exc_type, exc_value, tb)
  File "/Users/davemagarian/PycharmProjects/Meme-Flask/venv/lib/python3.7/site-packages/flask/_compat.py", line 39, in reraise
    raise value
  File "/Users/davemagarian/PycharmProjects/Meme-Flask/venv/lib/python3.7/site-packages/flask/app.py", line 1949, in full_dispatch_request
    rv = self.dispatch_request()
  File "/Users/davemagarian/PycharmProjects/Meme-Flask/venv/lib/python3.7/site-packages/flask/app.py", line 1935, in dispatch_request
    return self.view_functions[rule.endpoint](**req.view_args)
  File "/Users/davemagarian/PycharmProjects/Meme-Flask/app/views.py", line 192, in upldfile
    my_bucket.Object(filename).put(Body=combined)
  File "/Users/davemagarian/PycharmProjects/Meme-Flask/venv/lib/python3.7/site-packages/boto3/resources/factory.py", line 520, in do_action
    response = action(self, *args, **kwargs)
  File "/Users/davemagarian/PycharmProjects/Meme-Flask/venv/lib/python3.7/site-packages/boto3/resources/action.py", line 83, in __call__
    response = getattr(parent.meta.client, operation_name)(**params)
  File "/Users/davemagarian/PycharmProjects/Meme-Flask/venv/lib/python3.7/site-packages/botocore/client.py", line 357, in _api_call
    return self._make_api_call(operation_name, kwargs)
  File "/Users/davemagarian/PycharmProjects/Meme-Flask/venv/lib/python3.7/site-packages/botocore/client.py", line 634, in _make_api_call
    api_params, operation_model, context=request_context)
  File "/Users/davemagarian/PycharmProjects/Meme-Flask/venv/lib/python3.7/site-packages/botocore/client.py", line 682, in _convert_to_request_dict
    api_params, operation_model)
  File "/Users/davemagarian/PycharmProjects/Meme-Flask/venv/lib/python3.7/site-packages/botocore/validate.py", line 297, in serialize_to_request
    raise ParamValidationError(report=report.generate_report())
botocore.exceptions.ParamValidationError: Parameter validation failed:
Invalid type for parameter Body, value: <PIL.Image.Image image mode=RGBA size=1280x1069 at 0x115A24198>, type: <class 'PIL.Image.Image'>, valid types: <class 'bytes'>, <class 'bytearray'>, file-like object
[2019-10-27 08:02:13] ERROR    Exception on /uploadajax [POST]
Traceback (most recent call last):
  File "/Users/davemagarian/PycharmProjects/Meme-Flask/venv/lib/python3.7/site-packages/flask/app.py", line 2446, in wsgi_app
    response = self.full_dispatch_request()
  File "/Users/davemagarian/PycharmProjects/Meme-Flask/venv/lib/python3.7/site-packages/flask/app.py", line 1951, in full_dispatch_request
    rv = self.handle_user_exception(e)
  File "/Users/davemagarian/PycharmProjects/Meme-Flask/venv/lib/python3.7/site-packages/flask/app.py", line 1820, in handle_user_exception
    reraise(exc_type, exc_value, tb)
  File "/Users/davemagarian/PycharmProjects/Meme-Flask/venv/lib/python3.7/site-packages/flask/_compat.py", line 39, in reraise
    raise value
  File "/Users/davemagarian/PycharmProjects/Meme-Flask/venv/lib/python3.7/site-packages/flask/app.py", line 1949, in full_dispatch_request
    rv = self.dispatch_request()
  File "/Users/davemagarian/PycharmProjects/Meme-Flask/venv/lib/python3.7/site-packages/flask/app.py", line 1935, in dispatch_request
    return self.view_functions[rule.endpoint](**req.view_args)
  File "/Users/davemagarian/PycharmProjects/Meme-Flask/app/views.py", line 192, in upldfile
    my_bucket.Object(filename).put(Body=combined.read())
AttributeError: 'Image' object has no attribute 'read'
[2019-10-27 08:03:02] ERROR    Exception on /uploadajax [POST]
Traceback (most recent call last):
  File "/Users/davemagarian/PycharmProjects/Meme-Flask/venv/lib/python3.7/site-packages/flask/app.py", line 2446, in wsgi_app
    response = self.full_dispatch_request()
  File "/Users/davemagarian/PycharmProjects/Meme-Flask/venv/lib/python3.7/site-packages/flask/app.py", line 1951, in full_dispatch_request
    rv = self.handle_user_exception(e)
  File "/Users/davemagarian/PycharmProjects/Meme-Flask/venv/lib/python3.7/site-packages/flask/app.py", line 1820, in handle_user_exception
    reraise(exc_type, exc_value, tb)
  File "/Users/davemagarian/PycharmProjects/Meme-Flask/venv/lib/python3.7/site-packages/flask/_compat.py", line 39, in reraise
    raise value
  File "/Users/davemagarian/PycharmProjects/Meme-Flask/venv/lib/python3.7/site-packages/flask/app.py", line 1949, in full_dispatch_request
    rv = self.dispatch_request()
  File "/Users/davemagarian/PycharmProjects/Meme-Flask/venv/lib/python3.7/site-packages/flask/app.py", line 1935, in dispatch_request
    return self.view_functions[rule.endpoint](**req.view_args)
  File "/Users/davemagarian/PycharmProjects/Meme-Flask/app/views.py", line 192, in upldfile
    my_bucket.Object(combined).put(Body=combined)
  File "/Users/davemagarian/PycharmProjects/Meme-Flask/venv/lib/python3.7/site-packages/boto3/resources/factory.py", line 520, in do_action
    response = action(self, *args, **kwargs)
  File "/Users/davemagarian/PycharmProjects/Meme-Flask/venv/lib/python3.7/site-packages/boto3/resources/action.py", line 83, in __call__
    response = getattr(parent.meta.client, operation_name)(**params)
  File "/Users/davemagarian/PycharmProjects/Meme-Flask/venv/lib/python3.7/site-packages/botocore/client.py", line 357, in _api_call
    return self._make_api_call(operation_name, kwargs)
  File "/Users/davemagarian/PycharmProjects/Meme-Flask/venv/lib/python3.7/site-packages/botocore/client.py", line 634, in _make_api_call
    api_params, operation_model, context=request_context)
  File "/Users/davemagarian/PycharmProjects/Meme-Flask/venv/lib/python3.7/site-packages/botocore/client.py", line 682, in _convert_to_request_dict
    api_params, operation_model)
  File "/Users/davemagarian/PycharmProjects/Meme-Flask/venv/lib/python3.7/site-packages/botocore/validate.py", line 297, in serialize_to_request
    raise ParamValidationError(report=report.generate_report())
botocore.exceptions.ParamValidationError: Parameter validation failed:
Invalid type for parameter Key, value: <PIL.Image.Image image mode=RGBA size=1280x1069 at 0x111134240>, type: <class 'PIL.Image.Image'>, valid types: <class 'str'>
Invalid type for parameter Body, value: <PIL.Image.Image image mode=RGBA size=1280x1069 at 0x111134240>, type: <class 'PIL.Image.Image'>, valid types: <class 'bytes'>, <class 'bytearray'>, file-like object
[2019-10-27 08:05:17] ERROR    Exception on /uploadajax [POST]
Traceback (most recent call last):
  File "/Users/davemagarian/PycharmProjects/Meme-Flask/venv/lib/python3.7/site-packages/flask/app.py", line 2446, in wsgi_app
    response = self.full_dispatch_request()
  File "/Users/davemagarian/PycharmProjects/Meme-Flask/venv/lib/python3.7/site-packages/flask/app.py", line 1951, in full_dispatch_request
    rv = self.handle_user_exception(e)
  File "/Users/davemagarian/PycharmProjects/Meme-Flask/venv/lib/python3.7/site-packages/flask/app.py", line 1820, in handle_user_exception
    reraise(exc_type, exc_value, tb)
  File "/Users/davemagarian/PycharmProjects/Meme-Flask/venv/lib/python3.7/site-packages/flask/_compat.py", line 39, in reraise
    raise value
  File "/Users/davemagarian/PycharmProjects/Meme-Flask/venv/lib/python3.7/site-packages/flask/app.py", line 1949, in full_dispatch_request
    rv = self.dispatch_request()
  File "/Users/davemagarian/PycharmProjects/Meme-Flask/venv/lib/python3.7/site-packages/flask/app.py", line 1935, in dispatch_request
    return self.view_functions[rule.endpoint](**req.view_args)
  File "/Users/davemagarian/PycharmProjects/Meme-Flask/app/views.py", line 192, in upldfile
    my_bucket.Object(combined).put(Body=combined)
  File "/Users/davemagarian/PycharmProjects/Meme-Flask/venv/lib/python3.7/site-packages/boto3/resources/factory.py", line 520, in do_action
    response = action(self, *args, **kwargs)
  File "/Users/davemagarian/PycharmProjects/Meme-Flask/venv/lib/python3.7/site-packages/boto3/resources/action.py", line 83, in __call__
    response = getattr(parent.meta.client, operation_name)(**params)
  File "/Users/davemagarian/PycharmProjects/Meme-Flask/venv/lib/python3.7/site-packages/botocore/client.py", line 357, in _api_call
    return self._make_api_call(operation_name, kwargs)
  File "/Users/davemagarian/PycharmProjects/Meme-Flask/venv/lib/python3.7/site-packages/botocore/client.py", line 634, in _make_api_call
    api_params, operation_model, context=request_context)
  File "/Users/davemagarian/PycharmProjects/Meme-Flask/venv/lib/python3.7/site-packages/botocore/client.py", line 682, in _convert_to_request_dict
    api_params, operation_model)
  File "/Users/davemagarian/PycharmProjects/Meme-Flask/venv/lib/python3.7/site-packages/botocore/validate.py", line 297, in serialize_to_request
    raise ParamValidationError(report=report.generate_report())
botocore.exceptions.ParamValidationError: Parameter validation failed:
Invalid type for parameter Key, value: <PIL.Image.Image image mode=RGBA size=1280x1464 at 0x11E7F9710>, type: <class 'PIL.Image.Image'>, valid types: <class 'str'>
Invalid type for parameter Body, value: <PIL.Image.Image image mode=RGBA size=1280x1464 at 0x11E7F9710>, type: <class 'PIL.Image.Image'>, valid types: <class 'bytes'>, <class 'bytearray'>, file-like object
[2019-10-27 08:06:51] ERROR    Exception on /uploadajax [POST]
Traceback (most recent call last):
  File "/Users/davemagarian/PycharmProjects/Meme-Flask/venv/lib/python3.7/site-packages/flask/app.py", line 2446, in wsgi_app
    response = self.full_dispatch_request()
  File "/Users/davemagarian/PycharmProjects/Meme-Flask/venv/lib/python3.7/site-packages/flask/app.py", line 1951, in full_dispatch_request
    rv = self.handle_user_exception(e)
  File "/Users/davemagarian/PycharmProjects/Meme-Flask/venv/lib/python3.7/site-packages/flask/app.py", line 1820, in handle_user_exception
    reraise(exc_type, exc_value, tb)
  File "/Users/davemagarian/PycharmProjects/Meme-Flask/venv/lib/python3.7/site-packages/flask/_compat.py", line 39, in reraise
    raise value
  File "/Users/davemagarian/PycharmProjects/Meme-Flask/venv/lib/python3.7/site-packages/flask/app.py", line 1949, in full_dispatch_request
    rv = self.dispatch_request()
  File "/Users/davemagarian/PycharmProjects/Meme-Flask/venv/lib/python3.7/site-packages/flask/app.py", line 1935, in dispatch_request
    return self.view_functions[rule.endpoint](**req.view_args)
  File "/Users/davemagarian/PycharmProjects/Meme-Flask/app/views.py", line 192, in upldfile
    my_bucket.Object(newfilename).put(Body=combined)
  File "/Users/davemagarian/PycharmProjects/Meme-Flask/venv/lib/python3.7/site-packages/boto3/resources/factory.py", line 520, in do_action
    response = action(self, *args, **kwargs)
  File "/Users/davemagarian/PycharmProjects/Meme-Flask/venv/lib/python3.7/site-packages/boto3/resources/action.py", line 83, in __call__
    response = getattr(parent.meta.client, operation_name)(**params)
  File "/Users/davemagarian/PycharmProjects/Meme-Flask/venv/lib/python3.7/site-packages/botocore/client.py", line 357, in _api_call
    return self._make_api_call(operation_name, kwargs)
  File "/Users/davemagarian/PycharmProjects/Meme-Flask/venv/lib/python3.7/site-packages/botocore/client.py", line 634, in _make_api_call
    api_params, operation_model, context=request_context)
  File "/Users/davemagarian/PycharmProjects/Meme-Flask/venv/lib/python3.7/site-packages/botocore/client.py", line 682, in _convert_to_request_dict
    api_params, operation_model)
  File "/Users/davemagarian/PycharmProjects/Meme-Flask/venv/lib/python3.7/site-packages/botocore/validate.py", line 297, in serialize_to_request
    raise ParamValidationError(report=report.generate_report())
botocore.exceptions.ParamValidationError: Parameter validation failed:
Invalid type for parameter Key, value: <PIL.Image.Image image mode=RGBA size=1280x1252 at 0x11E434FD0>, type: <class 'PIL.Image.Image'>, valid types: <class 'str'>
Invalid type for parameter Body, value: <PIL.Image.Image image mode=RGBA size=1280x1252 at 0x11E434FD0>, type: <class 'PIL.Image.Image'>, valid types: <class 'bytes'>, <class 'bytearray'>, file-like object
[2019-10-27 08:07:08] ERROR    Exception on /uploadajax [POST]
Traceback (most recent call last):
  File "/Users/davemagarian/PycharmProjects/Meme-Flask/venv/lib/python3.7/site-packages/flask/app.py", line 2446, in wsgi_app
    response = self.full_dispatch_request()
  File "/Users/davemagarian/PycharmProjects/Meme-Flask/venv/lib/python3.7/site-packages/flask/app.py", line 1951, in full_dispatch_request
    rv = self.handle_user_exception(e)
  File "/Users/davemagarian/PycharmProjects/Meme-Flask/venv/lib/python3.7/site-packages/flask/app.py", line 1820, in handle_user_exception
    reraise(exc_type, exc_value, tb)
  File "/Users/davemagarian/PycharmProjects/Meme-Flask/venv/lib/python3.7/site-packages/flask/_compat.py", line 39, in reraise
    raise value
  File "/Users/davemagarian/PycharmProjects/Meme-Flask/venv/lib/python3.7/site-packages/flask/app.py", line 1949, in full_dispatch_request
    rv = self.dispatch_request()
  File "/Users/davemagarian/PycharmProjects/Meme-Flask/venv/lib/python3.7/site-packages/flask/app.py", line 1935, in dispatch_request
    return self.view_functions[rule.endpoint](**req.view_args)
  File "/Users/davemagarian/PycharmProjects/Meme-Flask/app/views.py", line 192, in upldfile
    my_bucket.Object(newfilename).put(Body=combined)
  File "/Users/davemagarian/PycharmProjects/Meme-Flask/venv/lib/python3.7/site-packages/boto3/resources/factory.py", line 520, in do_action
    response = action(self, *args, **kwargs)
  File "/Users/davemagarian/PycharmProjects/Meme-Flask/venv/lib/python3.7/site-packages/boto3/resources/action.py", line 83, in __call__
    response = getattr(parent.meta.client, operation_name)(**params)
  File "/Users/davemagarian/PycharmProjects/Meme-Flask/venv/lib/python3.7/site-packages/botocore/client.py", line 357, in _api_call
    return self._make_api_call(operation_name, kwargs)
  File "/Users/davemagarian/PycharmProjects/Meme-Flask/venv/lib/python3.7/site-packages/botocore/client.py", line 634, in _make_api_call
    api_params, operation_model, context=request_context)
  File "/Users/davemagarian/PycharmProjects/Meme-Flask/venv/lib/python3.7/site-packages/botocore/client.py", line 682, in _convert_to_request_dict
    api_params, operation_model)
  File "/Users/davemagarian/PycharmProjects/Meme-Flask/venv/lib/python3.7/site-packages/botocore/validate.py", line 297, in serialize_to_request
    raise ParamValidationError(report=report.generate_report())
botocore.exceptions.ParamValidationError: Parameter validation failed:
Invalid type for parameter Body, value: <PIL.Image.Image image mode=RGBA size=1280x1252 at 0x1118EEE48>, type: <class 'PIL.Image.Image'>, valid types: <class 'bytes'>, <class 'bytearray'>, file-like object
[2019-10-27 08:08:44] ERROR    Exception on /uploadajax [POST]
Traceback (most recent call last):
  File "/Users/davemagarian/PycharmProjects/Meme-Flask/venv/lib/python3.7/site-packages/flask/app.py", line 2446, in wsgi_app
    response = self.full_dispatch_request()
  File "/Users/davemagarian/PycharmProjects/Meme-Flask/venv/lib/python3.7/site-packages/flask/app.py", line 1951, in full_dispatch_request
    rv = self.handle_user_exception(e)
  File "/Users/davemagarian/PycharmProjects/Meme-Flask/venv/lib/python3.7/site-packages/flask/app.py", line 1820, in handle_user_exception
    reraise(exc_type, exc_value, tb)
  File "/Users/davemagarian/PycharmProjects/Meme-Flask/venv/lib/python3.7/site-packages/flask/_compat.py", line 39, in reraise
    raise value
  File "/Users/davemagarian/PycharmProjects/Meme-Flask/venv/lib/python3.7/site-packages/flask/app.py", line 1949, in full_dispatch_request
    rv = self.dispatch_request()
  File "/Users/davemagarian/PycharmProjects/Meme-Flask/venv/lib/python3.7/site-packages/flask/app.py", line 1935, in dispatch_request
    return self.view_functions[rule.endpoint](**req.view_args)
  File "/Users/davemagarian/PycharmProjects/Meme-Flask/app/views.py", line 193, in upldfile
    my_bucket.Object(newfilename).put(Body=combined)
  File "/Users/davemagarian/PycharmProjects/Meme-Flask/venv/lib/python3.7/site-packages/boto3/resources/factory.py", line 520, in do_action
    response = action(self, *args, **kwargs)
  File "/Users/davemagarian/PycharmProjects/Meme-Flask/venv/lib/python3.7/site-packages/boto3/resources/action.py", line 83, in __call__
    response = getattr(parent.meta.client, operation_name)(**params)
  File "/Users/davemagarian/PycharmProjects/Meme-Flask/venv/lib/python3.7/site-packages/botocore/client.py", line 357, in _api_call
    return self._make_api_call(operation_name, kwargs)
  File "/Users/davemagarian/PycharmProjects/Meme-Flask/venv/lib/python3.7/site-packages/botocore/client.py", line 634, in _make_api_call
    api_params, operation_model, context=request_context)
  File "/Users/davemagarian/PycharmProjects/Meme-Flask/venv/lib/python3.7/site-packages/botocore/client.py", line 682, in _convert_to_request_dict
    api_params, operation_model)
  File "/Users/davemagarian/PycharmProjects/Meme-Flask/venv/lib/python3.7/site-packages/botocore/validate.py", line 297, in serialize_to_request
    raise ParamValidationError(report=report.generate_report())
botocore.exceptions.ParamValidationError: Parameter validation failed:
Invalid type for parameter Body, value: <PIL.Image.Image image mode=RGBA size=1280x1252 at 0x113861240>, type: <class 'PIL.Image.Image'>, valid types: <class 'bytes'>, <class 'bytearray'>, file-like object
[2019-10-27 08:10:54] ERROR    Exception on /uploadajax [POST]
Traceback (most recent call last):
  File "/Users/davemagarian/PycharmProjects/Meme-Flask/venv/lib/python3.7/site-packages/flask/app.py", line 2446, in wsgi_app
    response = self.full_dispatch_request()
  File "/Users/davemagarian/PycharmProjects/Meme-Flask/venv/lib/python3.7/site-packages/flask/app.py", line 1951, in full_dispatch_request
    rv = self.handle_user_exception(e)
  File "/Users/davemagarian/PycharmProjects/Meme-Flask/venv/lib/python3.7/site-packages/flask/app.py", line 1820, in handle_user_exception
    reraise(exc_type, exc_value, tb)
  File "/Users/davemagarian/PycharmProjects/Meme-Flask/venv/lib/python3.7/site-packages/flask/_compat.py", line 39, in reraise
    raise value
  File "/Users/davemagarian/PycharmProjects/Meme-Flask/venv/lib/python3.7/site-packages/flask/app.py", line 1949, in full_dispatch_request
    rv = self.dispatch_request()
  File "/Users/davemagarian/PycharmProjects/Meme-Flask/venv/lib/python3.7/site-packages/flask/app.py", line 1935, in dispatch_request
    return self.view_functions[rule.endpoint](**req.view_args)
  File "/Users/davemagarian/PycharmProjects/Meme-Flask/app/views.py", line 187, in upldfile
    imgByteArr = combined.getvalue()
AttributeError: 'Image' object has no attribute 'getvalue'
[2019-10-27 08:12:51] ERROR    Exception on /uploadajax [POST]
Traceback (most recent call last):
  File "/Users/davemagarian/PycharmProjects/Meme-Flask/venv/lib/python3.7/site-packages/flask/app.py", line 2446, in wsgi_app
    response = self.full_dispatch_request()
  File "/Users/davemagarian/PycharmProjects/Meme-Flask/venv/lib/python3.7/site-packages/flask/app.py", line 1952, in full_dispatch_request
    return self.finalize_request(rv)
  File "/Users/davemagarian/PycharmProjects/Meme-Flask/venv/lib/python3.7/site-packages/flask/app.py", line 1967, in finalize_request
    response = self.make_response(rv)
  File "/Users/davemagarian/PycharmProjects/Meme-Flask/venv/lib/python3.7/site-packages/flask/app.py", line 2097, in make_response
    "The view function did not return a valid response. The"
TypeError: The view function did not return a valid response. The function either returned None or ended without a return statement.
[2019-10-27 08:16:09] ERROR    Exception on /uploadajax [POST]
Traceback (most recent call last):
  File "/Users/davemagarian/PycharmProjects/Meme-Flask/venv/lib/python3.7/site-packages/flask/app.py", line 2446, in wsgi_app
    response = self.full_dispatch_request()
  File "/Users/davemagarian/PycharmProjects/Meme-Flask/venv/lib/python3.7/site-packages/flask/app.py", line 1952, in full_dispatch_request
    return self.finalize_request(rv)
  File "/Users/davemagarian/PycharmProjects/Meme-Flask/venv/lib/python3.7/site-packages/flask/app.py", line 1967, in finalize_request
    response = self.make_response(rv)
  File "/Users/davemagarian/PycharmProjects/Meme-Flask/venv/lib/python3.7/site-packages/flask/app.py", line 2097, in make_response
    "The view function did not return a valid response. The"
TypeError: The view function did not return a valid response. The function either returned None or ended without a return statement.
[2019-10-27 08:17:09] ERROR    Exception on /uploadajax [POST]
Traceback (most recent call last):
  File "/Users/davemagarian/PycharmProjects/Meme-Flask/venv/lib/python3.7/site-packages/flask/app.py", line 2446, in wsgi_app
    response = self.full_dispatch_request()
  File "/Users/davemagarian/PycharmProjects/Meme-Flask/venv/lib/python3.7/site-packages/flask/app.py", line 1952, in full_dispatch_request
    return self.finalize_request(rv)
  File "/Users/davemagarian/PycharmProjects/Meme-Flask/venv/lib/python3.7/site-packages/flask/app.py", line 1967, in finalize_request
    response = self.make_response(rv)
  File "/Users/davemagarian/PycharmProjects/Meme-Flask/venv/lib/python3.7/site-packages/flask/app.py", line 2097, in make_response
    "The view function did not return a valid response. The"
TypeError: The view function did not return a valid response. The function either returned None or ended without a return statement.
[2019-10-27 08:17:33] ERROR    Exception on /uploadajax [POST]
Traceback (most recent call last):
  File "/Users/davemagarian/PycharmProjects/Meme-Flask/venv/lib/python3.7/site-packages/flask/app.py", line 2446, in wsgi_app
    response = self.full_dispatch_request()
  File "/Users/davemagarian/PycharmProjects/Meme-Flask/venv/lib/python3.7/site-packages/flask/app.py", line 1952, in full_dispatch_request
    return self.finalize_request(rv)
  File "/Users/davemagarian/PycharmProjects/Meme-Flask/venv/lib/python3.7/site-packages/flask/app.py", line 1967, in finalize_request
    response = self.make_response(rv)
  File "/Users/davemagarian/PycharmProjects/Meme-Flask/venv/lib/python3.7/site-packages/flask/app.py", line 2097, in make_response
    "The view function did not return a valid response. The"
TypeError: The view function did not return a valid response. The function either returned None or ended without a return statement.
[2019-10-27 08:28:51] ERROR    Exception on /uploadajax [POST]
Traceback (most recent call last):
  File "/Users/davemagarian/PycharmProjects/Meme-Flask/venv/lib/python3.7/site-packages/flask/app.py", line 2446, in wsgi_app
    response = self.full_dispatch_request()
  File "/Users/davemagarian/PycharmProjects/Meme-Flask/venv/lib/python3.7/site-packages/flask/app.py", line 1951, in full_dispatch_request
    rv = self.handle_user_exception(e)
  File "/Users/davemagarian/PycharmProjects/Meme-Flask/venv/lib/python3.7/site-packages/flask/app.py", line 1820, in handle_user_exception
    reraise(exc_type, exc_value, tb)
  File "/Users/davemagarian/PycharmProjects/Meme-Flask/venv/lib/python3.7/site-packages/flask/_compat.py", line 39, in reraise
    raise value
  File "/Users/davemagarian/PycharmProjects/Meme-Flask/venv/lib/python3.7/site-packages/flask/app.py", line 1949, in full_dispatch_request
    rv = self.dispatch_request()
  File "/Users/davemagarian/PycharmProjects/Meme-Flask/venv/lib/python3.7/site-packages/flask/app.py", line 1935, in dispatch_request
    return self.view_functions[rule.endpoint](**req.view_args)
  File "/Users/davemagarian/PycharmProjects/Meme-Flask/app/views.py", line 195, in upldfile
    my_bucket.upload_file(newfilename, imgByteArr )
  File "/Users/davemagarian/PycharmProjects/Meme-Flask/venv/lib/python3.7/site-packages/boto3/s3/inject.py", line 209, in bucket_upload_file
    ExtraArgs=ExtraArgs, Callback=Callback, Config=Config)
  File "/Users/davemagarian/PycharmProjects/Meme-Flask/venv/lib/python3.7/site-packages/boto3/s3/inject.py", line 131, in upload_file
    extra_args=ExtraArgs, callback=Callback)
  File "/Users/davemagarian/PycharmProjects/Meme-Flask/venv/lib/python3.7/site-packages/boto3/s3/transfer.py", line 279, in upload_file
    future.result()
  File "/Users/davemagarian/PycharmProjects/Meme-Flask/venv/lib/python3.7/site-packages/s3transfer/futures.py", line 106, in result
    return self._coordinator.result()
  File "/Users/davemagarian/PycharmProjects/Meme-Flask/venv/lib/python3.7/site-packages/s3transfer/futures.py", line 265, in result
    raise self._exception
  File "/Users/davemagarian/PycharmProjects/Meme-Flask/venv/lib/python3.7/site-packages/s3transfer/tasks.py", line 255, in _main
    self._submit(transfer_future=transfer_future, **kwargs)
  File "/Users/davemagarian/PycharmProjects/Meme-Flask/venv/lib/python3.7/site-packages/s3transfer/upload.py", line 549, in _submit
    upload_input_manager.provide_transfer_size(transfer_future)
  File "/Users/davemagarian/PycharmProjects/Meme-Flask/venv/lib/python3.7/site-packages/s3transfer/upload.py", line 237, in provide_transfer_size
    transfer_future.meta.call_args.fileobj))
  File "/Users/davemagarian/PycharmProjects/Meme-Flask/venv/lib/python3.7/site-packages/s3transfer/utils.py", line 243, in get_file_size
    return os.path.getsize(filename)
  File "/Library/Frameworks/Python.framework/Versions/3.7/lib/python3.7/genericpath.py", line 50, in getsize
    return os.stat(filename).st_size
FileNotFoundError: [Errno 2] No such file or directory: 'IMG_0454.JPG.png'
[2019-10-27 08:30:15] ERROR    Exception on /uploadajax [POST]
Traceback (most recent call last):
  File "/Users/davemagarian/PycharmProjects/Meme-Flask/venv/lib/python3.7/site-packages/flask/app.py", line 2446, in wsgi_app
    response = self.full_dispatch_request()
  File "/Users/davemagarian/PycharmProjects/Meme-Flask/venv/lib/python3.7/site-packages/flask/app.py", line 1951, in full_dispatch_request
    rv = self.handle_user_exception(e)
  File "/Users/davemagarian/PycharmProjects/Meme-Flask/venv/lib/python3.7/site-packages/flask/app.py", line 1820, in handle_user_exception
    reraise(exc_type, exc_value, tb)
  File "/Users/davemagarian/PycharmProjects/Meme-Flask/venv/lib/python3.7/site-packages/flask/_compat.py", line 39, in reraise
    raise value
  File "/Users/davemagarian/PycharmProjects/Meme-Flask/venv/lib/python3.7/site-packages/flask/app.py", line 1949, in full_dispatch_request
    rv = self.dispatch_request()
  File "/Users/davemagarian/PycharmProjects/Meme-Flask/venv/lib/python3.7/site-packages/flask/app.py", line 1935, in dispatch_request
    return self.view_functions[rule.endpoint](**req.view_args)
  File "/Users/davemagarian/PycharmProjects/Meme-Flask/app/views.py", line 195, in upldfile
    my_bucket.upload_file(newfilename, imgByteArr )
  File "/Users/davemagarian/PycharmProjects/Meme-Flask/venv/lib/python3.7/site-packages/boto3/s3/inject.py", line 209, in bucket_upload_file
    ExtraArgs=ExtraArgs, Callback=Callback, Config=Config)
  File "/Users/davemagarian/PycharmProjects/Meme-Flask/venv/lib/python3.7/site-packages/boto3/s3/inject.py", line 131, in upload_file
    extra_args=ExtraArgs, callback=Callback)
  File "/Users/davemagarian/PycharmProjects/Meme-Flask/venv/lib/python3.7/site-packages/boto3/s3/transfer.py", line 279, in upload_file
    future.result()
  File "/Users/davemagarian/PycharmProjects/Meme-Flask/venv/lib/python3.7/site-packages/s3transfer/futures.py", line 106, in result
    return self._coordinator.result()
  File "/Users/davemagarian/PycharmProjects/Meme-Flask/venv/lib/python3.7/site-packages/s3transfer/futures.py", line 265, in result
    raise self._exception
  File "/Users/davemagarian/PycharmProjects/Meme-Flask/venv/lib/python3.7/site-packages/s3transfer/tasks.py", line 255, in _main
    self._submit(transfer_future=transfer_future, **kwargs)
  File "/Users/davemagarian/PycharmProjects/Meme-Flask/venv/lib/python3.7/site-packages/s3transfer/upload.py", line 549, in _submit
    upload_input_manager.provide_transfer_size(transfer_future)
  File "/Users/davemagarian/PycharmProjects/Meme-Flask/venv/lib/python3.7/site-packages/s3transfer/upload.py", line 237, in provide_transfer_size
    transfer_future.meta.call_args.fileobj))
  File "/Users/davemagarian/PycharmProjects/Meme-Flask/venv/lib/python3.7/site-packages/s3transfer/utils.py", line 243, in get_file_size
    return os.path.getsize(filename)
  File "/Library/Frameworks/Python.framework/Versions/3.7/lib/python3.7/genericpath.py", line 50, in getsize
    return os.stat(filename).st_size
FileNotFoundError: [Errno 2] No such file or directory: 'but-wait-theres-more-44084002.png.png'
[2019-10-27 08:31:58] ERROR    Exception on /uploadajax [POST]
Traceback (most recent call last):
  File "/Users/davemagarian/PycharmProjects/Meme-Flask/venv/lib/python3.7/site-packages/flask/app.py", line 2446, in wsgi_app
    response = self.full_dispatch_request()
  File "/Users/davemagarian/PycharmProjects/Meme-Flask/venv/lib/python3.7/site-packages/flask/app.py", line 1951, in full_dispatch_request
    rv = self.handle_user_exception(e)
  File "/Users/davemagarian/PycharmProjects/Meme-Flask/venv/lib/python3.7/site-packages/flask/app.py", line 1820, in handle_user_exception
    reraise(exc_type, exc_value, tb)
  File "/Users/davemagarian/PycharmProjects/Meme-Flask/venv/lib/python3.7/site-packages/flask/_compat.py", line 39, in reraise
    raise value
  File "/Users/davemagarian/PycharmProjects/Meme-Flask/venv/lib/python3.7/site-packages/flask/app.py", line 1949, in full_dispatch_request
    rv = self.dispatch_request()
  File "/Users/davemagarian/PycharmProjects/Meme-Flask/venv/lib/python3.7/site-packages/flask/app.py", line 1935, in dispatch_request
    return self.view_functions[rule.endpoint](**req.view_args)
  File "/Users/davemagarian/PycharmProjects/Meme-Flask/app/views.py", line 195, in upldfile
    my_bucket.upload_file(newfilename, imgByteArr )
  File "/Users/davemagarian/PycharmProjects/Meme-Flask/venv/lib/python3.7/site-packages/boto3/s3/inject.py", line 209, in bucket_upload_file
    ExtraArgs=ExtraArgs, Callback=Callback, Config=Config)
  File "/Users/davemagarian/PycharmProjects/Meme-Flask/venv/lib/python3.7/site-packages/boto3/s3/inject.py", line 131, in upload_file
    extra_args=ExtraArgs, callback=Callback)
  File "/Users/davemagarian/PycharmProjects/Meme-Flask/venv/lib/python3.7/site-packages/boto3/s3/transfer.py", line 279, in upload_file
    future.result()
  File "/Users/davemagarian/PycharmProjects/Meme-Flask/venv/lib/python3.7/site-packages/s3transfer/futures.py", line 106, in result
    return self._coordinator.result()
  File "/Users/davemagarian/PycharmProjects/Meme-Flask/venv/lib/python3.7/site-packages/s3transfer/futures.py", line 265, in result
    raise self._exception
  File "/Users/davemagarian/PycharmProjects/Meme-Flask/venv/lib/python3.7/site-packages/s3transfer/tasks.py", line 255, in _main
    self._submit(transfer_future=transfer_future, **kwargs)
  File "/Users/davemagarian/PycharmProjects/Meme-Flask/venv/lib/python3.7/site-packages/s3transfer/upload.py", line 549, in _submit
    upload_input_manager.provide_transfer_size(transfer_future)
  File "/Users/davemagarian/PycharmProjects/Meme-Flask/venv/lib/python3.7/site-packages/s3transfer/upload.py", line 237, in provide_transfer_size
    transfer_future.meta.call_args.fileobj))
  File "/Users/davemagarian/PycharmProjects/Meme-Flask/venv/lib/python3.7/site-packages/s3transfer/utils.py", line 243, in get_file_size
    return os.path.getsize(filename)
  File "/Library/Frameworks/Python.framework/Versions/3.7/lib/python3.7/genericpath.py", line 50, in getsize
    return os.stat(filename).st_size
FileNotFoundError: [Errno 2] No such file or directory: 'IMG_F4DB90F74EF6-1.jpeg.png'
[2019-10-27 08:36:38] ERROR    Exception on /uploadajax [POST]
Traceback (most recent call last):
  File "/Users/davemagarian/PycharmProjects/Meme-Flask/venv/lib/python3.7/site-packages/flask/app.py", line 2446, in wsgi_app
    response = self.full_dispatch_request()
  File "/Users/davemagarian/PycharmProjects/Meme-Flask/venv/lib/python3.7/site-packages/flask/app.py", line 1951, in full_dispatch_request
    rv = self.handle_user_exception(e)
  File "/Users/davemagarian/PycharmProjects/Meme-Flask/venv/lib/python3.7/site-packages/flask/app.py", line 1820, in handle_user_exception
    reraise(exc_type, exc_value, tb)
  File "/Users/davemagarian/PycharmProjects/Meme-Flask/venv/lib/python3.7/site-packages/flask/_compat.py", line 39, in reraise
    raise value
  File "/Users/davemagarian/PycharmProjects/Meme-Flask/venv/lib/python3.7/site-packages/flask/app.py", line 1949, in full_dispatch_request
    rv = self.dispatch_request()
  File "/Users/davemagarian/PycharmProjects/Meme-Flask/venv/lib/python3.7/site-packages/flask/app.py", line 1935, in dispatch_request
    return self.view_functions[rule.endpoint](**req.view_args)
  File "/Users/davemagarian/PycharmProjects/Meme-Flask/app/views.py", line 195, in upldfile
    my_bucket.upload_file(newfilename, imgByteArr )
  File "/Users/davemagarian/PycharmProjects/Meme-Flask/venv/lib/python3.7/site-packages/boto3/s3/inject.py", line 209, in bucket_upload_file
    ExtraArgs=ExtraArgs, Callback=Callback, Config=Config)
  File "/Users/davemagarian/PycharmProjects/Meme-Flask/venv/lib/python3.7/site-packages/boto3/s3/inject.py", line 131, in upload_file
    extra_args=ExtraArgs, callback=Callback)
  File "/Users/davemagarian/PycharmProjects/Meme-Flask/venv/lib/python3.7/site-packages/boto3/s3/transfer.py", line 279, in upload_file
    future.result()
  File "/Users/davemagarian/PycharmProjects/Meme-Flask/venv/lib/python3.7/site-packages/s3transfer/futures.py", line 106, in result
    return self._coordinator.result()
  File "/Users/davemagarian/PycharmProjects/Meme-Flask/venv/lib/python3.7/site-packages/s3transfer/futures.py", line 265, in result
    raise self._exception
  File "/Users/davemagarian/PycharmProjects/Meme-Flask/venv/lib/python3.7/site-packages/s3transfer/tasks.py", line 255, in _main
    self._submit(transfer_future=transfer_future, **kwargs)
  File "/Users/davemagarian/PycharmProjects/Meme-Flask/venv/lib/python3.7/site-packages/s3transfer/upload.py", line 549, in _submit
    upload_input_manager.provide_transfer_size(transfer_future)
  File "/Users/davemagarian/PycharmProjects/Meme-Flask/venv/lib/python3.7/site-packages/s3transfer/upload.py", line 237, in provide_transfer_size
    transfer_future.meta.call_args.fileobj))
  File "/Users/davemagarian/PycharmProjects/Meme-Flask/venv/lib/python3.7/site-packages/s3transfer/utils.py", line 243, in get_file_size
    return os.path.getsize(filename)
  File "/Library/Frameworks/Python.framework/Versions/3.7/lib/python3.7/genericpath.py", line 50, in getsize
    return os.stat(filename).st_size
FileNotFoundError: [Errno 2] No such file or directory: 'Image_from_iOS.jpg.png'
[2019-10-27 09:59:06] ERROR    Exception on /uploadajax [POST]
Traceback (most recent call last):
  File "/Users/davemagarian/PycharmProjects/Meme-Flask/venv/lib/python3.7/site-packages/flask/app.py", line 2446, in wsgi_app
    response = self.full_dispatch_request()
  File "/Users/davemagarian/PycharmProjects/Meme-Flask/venv/lib/python3.7/site-packages/flask/app.py", line 1951, in full_dispatch_request
    rv = self.handle_user_exception(e)
  File "/Users/davemagarian/PycharmProjects/Meme-Flask/venv/lib/python3.7/site-packages/flask/app.py", line 1820, in handle_user_exception
    reraise(exc_type, exc_value, tb)
  File "/Users/davemagarian/PycharmProjects/Meme-Flask/venv/lib/python3.7/site-packages/flask/_compat.py", line 39, in reraise
    raise value
  File "/Users/davemagarian/PycharmProjects/Meme-Flask/venv/lib/python3.7/site-packages/flask/app.py", line 1949, in full_dispatch_request
    rv = self.dispatch_request()
  File "/Users/davemagarian/PycharmProjects/Meme-Flask/venv/lib/python3.7/site-packages/flask/app.py", line 1935, in dispatch_request
    return self.view_functions[rule.endpoint](**req.view_args)
  File "/Users/davemagarian/PycharmProjects/Meme-Flask/app/views.py", line 198, in upldfile
    return jsonify(byte=imgByteArr)
  File "/Users/davemagarian/PycharmProjects/Meme-Flask/venv/lib/python3.7/site-packages/flask/json/__init__.py", line 370, in jsonify
    dumps(data, indent=indent, separators=separators) + "\n",
  File "/Users/davemagarian/PycharmProjects/Meme-Flask/venv/lib/python3.7/site-packages/flask/json/__init__.py", line 211, in dumps
    rv = _json.dumps(obj, **kwargs)
  File "/Library/Frameworks/Python.framework/Versions/3.7/lib/python3.7/json/__init__.py", line 238, in dumps
    **kw).encode(obj)
  File "/Library/Frameworks/Python.framework/Versions/3.7/lib/python3.7/json/encoder.py", line 199, in encode
    chunks = self.iterencode(o, _one_shot=True)
  File "/Library/Frameworks/Python.framework/Versions/3.7/lib/python3.7/json/encoder.py", line 257, in iterencode
    return _iterencode(o, 0)
  File "/Users/davemagarian/PycharmProjects/Meme-Flask/venv/lib/python3.7/site-packages/flask/json/__init__.py", line 100, in default
    return _json.JSONEncoder.default(self, o)
  File "/Library/Frameworks/Python.framework/Versions/3.7/lib/python3.7/json/encoder.py", line 179, in default
    raise TypeError(f'Object of type {o.__class__.__name__} '
TypeError: Object of type bytes is not JSON serializable
[2019-10-27 09:59:11] ERROR    Exception on /uploadajax [POST]
Traceback (most recent call last):
  File "/Users/davemagarian/PycharmProjects/Meme-Flask/venv/lib/python3.7/site-packages/flask/app.py", line 2446, in wsgi_app
    response = self.full_dispatch_request()
  File "/Users/davemagarian/PycharmProjects/Meme-Flask/venv/lib/python3.7/site-packages/flask/app.py", line 1951, in full_dispatch_request
    rv = self.handle_user_exception(e)
  File "/Users/davemagarian/PycharmProjects/Meme-Flask/venv/lib/python3.7/site-packages/flask/app.py", line 1820, in handle_user_exception
    reraise(exc_type, exc_value, tb)
  File "/Users/davemagarian/PycharmProjects/Meme-Flask/venv/lib/python3.7/site-packages/flask/_compat.py", line 39, in reraise
    raise value
  File "/Users/davemagarian/PycharmProjects/Meme-Flask/venv/lib/python3.7/site-packages/flask/app.py", line 1949, in full_dispatch_request
    rv = self.dispatch_request()
  File "/Users/davemagarian/PycharmProjects/Meme-Flask/venv/lib/python3.7/site-packages/flask/app.py", line 1935, in dispatch_request
    return self.view_functions[rule.endpoint](**req.view_args)
  File "/Users/davemagarian/PycharmProjects/Meme-Flask/app/views.py", line 198, in upldfile
    return jsonify(byte=imgByteArr)
  File "/Users/davemagarian/PycharmProjects/Meme-Flask/venv/lib/python3.7/site-packages/flask/json/__init__.py", line 370, in jsonify
    dumps(data, indent=indent, separators=separators) + "\n",
  File "/Users/davemagarian/PycharmProjects/Meme-Flask/venv/lib/python3.7/site-packages/flask/json/__init__.py", line 211, in dumps
    rv = _json.dumps(obj, **kwargs)
  File "/Library/Frameworks/Python.framework/Versions/3.7/lib/python3.7/json/__init__.py", line 238, in dumps
    **kw).encode(obj)
  File "/Library/Frameworks/Python.framework/Versions/3.7/lib/python3.7/json/encoder.py", line 199, in encode
    chunks = self.iterencode(o, _one_shot=True)
  File "/Library/Frameworks/Python.framework/Versions/3.7/lib/python3.7/json/encoder.py", line 257, in iterencode
    return _iterencode(o, 0)
  File "/Users/davemagarian/PycharmProjects/Meme-Flask/venv/lib/python3.7/site-packages/flask/json/__init__.py", line 100, in default
    return _json.JSONEncoder.default(self, o)
  File "/Library/Frameworks/Python.framework/Versions/3.7/lib/python3.7/json/encoder.py", line 179, in default
    raise TypeError(f'Object of type {o.__class__.__name__} '
TypeError: Object of type bytes is not JSON serializable
[2019-10-27 10:00:21] ERROR    Exception on /uploadajax [POST]
Traceback (most recent call last):
  File "/Users/davemagarian/PycharmProjects/Meme-Flask/venv/lib/python3.7/site-packages/flask/app.py", line 2446, in wsgi_app
    response = self.full_dispatch_request()
  File "/Users/davemagarian/PycharmProjects/Meme-Flask/venv/lib/python3.7/site-packages/flask/app.py", line 1951, in full_dispatch_request
    rv = self.handle_user_exception(e)
  File "/Users/davemagarian/PycharmProjects/Meme-Flask/venv/lib/python3.7/site-packages/flask/app.py", line 1820, in handle_user_exception
    reraise(exc_type, exc_value, tb)
  File "/Users/davemagarian/PycharmProjects/Meme-Flask/venv/lib/python3.7/site-packages/flask/_compat.py", line 39, in reraise
    raise value
  File "/Users/davemagarian/PycharmProjects/Meme-Flask/venv/lib/python3.7/site-packages/flask/app.py", line 1949, in full_dispatch_request
    rv = self.dispatch_request()
  File "/Users/davemagarian/PycharmProjects/Meme-Flask/venv/lib/python3.7/site-packages/flask/app.py", line 1935, in dispatch_request
    return self.view_functions[rule.endpoint](**req.view_args)
  File "/Users/davemagarian/PycharmProjects/Meme-Flask/app/views.py", line 198, in upldfile
    return jsonify(byte=saved_meme)
  File "/Users/davemagarian/PycharmProjects/Meme-Flask/venv/lib/python3.7/site-packages/flask/json/__init__.py", line 370, in jsonify
    dumps(data, indent=indent, separators=separators) + "\n",
  File "/Users/davemagarian/PycharmProjects/Meme-Flask/venv/lib/python3.7/site-packages/flask/json/__init__.py", line 211, in dumps
    rv = _json.dumps(obj, **kwargs)
  File "/Library/Frameworks/Python.framework/Versions/3.7/lib/python3.7/json/__init__.py", line 238, in dumps
    **kw).encode(obj)
  File "/Library/Frameworks/Python.framework/Versions/3.7/lib/python3.7/json/encoder.py", line 199, in encode
    chunks = self.iterencode(o, _one_shot=True)
  File "/Library/Frameworks/Python.framework/Versions/3.7/lib/python3.7/json/encoder.py", line 257, in iterencode
    return _iterencode(o, 0)
  File "/Users/davemagarian/PycharmProjects/Meme-Flask/venv/lib/python3.7/site-packages/flask/json/__init__.py", line 100, in default
    return _json.JSONEncoder.default(self, o)
  File "/Library/Frameworks/Python.framework/Versions/3.7/lib/python3.7/json/encoder.py", line 179, in default
    raise TypeError(f'Object of type {o.__class__.__name__} '
TypeError: Object of type bytes is not JSON serializable
[2019-10-27 10:06:31] ERROR    Exception on /uploadajax [POST]
Traceback (most recent call last):
  File "/Users/davemagarian/PycharmProjects/Meme-Flask/venv/lib/python3.7/site-packages/flask/app.py", line 2446, in wsgi_app
    response = self.full_dispatch_request()
  File "/Users/davemagarian/PycharmProjects/Meme-Flask/venv/lib/python3.7/site-packages/flask/app.py", line 1951, in full_dispatch_request
    rv = self.handle_user_exception(e)
  File "/Users/davemagarian/PycharmProjects/Meme-Flask/venv/lib/python3.7/site-packages/flask/app.py", line 1820, in handle_user_exception
    reraise(exc_type, exc_value, tb)
  File "/Users/davemagarian/PycharmProjects/Meme-Flask/venv/lib/python3.7/site-packages/flask/_compat.py", line 39, in reraise
    raise value
  File "/Users/davemagarian/PycharmProjects/Meme-Flask/venv/lib/python3.7/site-packages/flask/app.py", line 1949, in full_dispatch_request
    rv = self.dispatch_request()
  File "/Users/davemagarian/PycharmProjects/Meme-Flask/venv/lib/python3.7/site-packages/flask/app.py", line 1935, in dispatch_request
    return self.view_functions[rule.endpoint](**req.view_args)
  File "/Users/davemagarian/PycharmProjects/Meme-Flask/app/views.py", line 189, in upldfile
    base64.b64encode
NameError: name 'base64' is not defined
[2019-10-27 10:06:53] ERROR    Exception on /uploadajax [POST]
Traceback (most recent call last):
  File "/Users/davemagarian/PycharmProjects/Meme-Flask/venv/lib/python3.7/site-packages/flask/app.py", line 2446, in wsgi_app
    response = self.full_dispatch_request()
  File "/Users/davemagarian/PycharmProjects/Meme-Flask/venv/lib/python3.7/site-packages/flask/app.py", line 1951, in full_dispatch_request
    rv = self.handle_user_exception(e)
  File "/Users/davemagarian/PycharmProjects/Meme-Flask/venv/lib/python3.7/site-packages/flask/app.py", line 1820, in handle_user_exception
    reraise(exc_type, exc_value, tb)
  File "/Users/davemagarian/PycharmProjects/Meme-Flask/venv/lib/python3.7/site-packages/flask/_compat.py", line 39, in reraise
    raise value
  File "/Users/davemagarian/PycharmProjects/Meme-Flask/venv/lib/python3.7/site-packages/flask/app.py", line 1949, in full_dispatch_request
    rv = self.dispatch_request()
  File "/Users/davemagarian/PycharmProjects/Meme-Flask/venv/lib/python3.7/site-packages/flask/app.py", line 1935, in dispatch_request
    return self.view_functions[rule.endpoint](**req.view_args)
  File "/Users/davemagarian/PycharmProjects/Meme-Flask/app/views.py", line 189, in upldfile
NameError: name 'base64' is not defined
[2019-10-27 10:07:33] ERROR    Exception on /uploadajax [POST]
Traceback (most recent call last):
  File "/Users/davemagarian/PycharmProjects/Meme-Flask/venv/lib/python3.7/site-packages/flask/app.py", line 2446, in wsgi_app
    response = self.full_dispatch_request()
  File "/Users/davemagarian/PycharmProjects/Meme-Flask/venv/lib/python3.7/site-packages/flask/app.py", line 1951, in full_dispatch_request
    rv = self.handle_user_exception(e)
  File "/Users/davemagarian/PycharmProjects/Meme-Flask/venv/lib/python3.7/site-packages/flask/app.py", line 1820, in handle_user_exception
    reraise(exc_type, exc_value, tb)
  File "/Users/davemagarian/PycharmProjects/Meme-Flask/venv/lib/python3.7/site-packages/flask/_compat.py", line 39, in reraise
    raise value
  File "/Users/davemagarian/PycharmProjects/Meme-Flask/venv/lib/python3.7/site-packages/flask/app.py", line 1949, in full_dispatch_request
    rv = self.dispatch_request()
  File "/Users/davemagarian/PycharmProjects/Meme-Flask/venv/lib/python3.7/site-packages/flask/app.py", line 1935, in dispatch_request
    return self.view_functions[rule.endpoint](**req.view_args)
  File "/Users/davemagarian/PycharmProjects/Meme-Flask/app/views.py", line 198, in upldfile
    return jsonify(byte=combined)
  File "/Users/davemagarian/PycharmProjects/Meme-Flask/venv/lib/python3.7/site-packages/flask/json/__init__.py", line 370, in jsonify
    dumps(data, indent=indent, separators=separators) + "\n",
  File "/Users/davemagarian/PycharmProjects/Meme-Flask/venv/lib/python3.7/site-packages/flask/json/__init__.py", line 211, in dumps
    rv = _json.dumps(obj, **kwargs)
  File "/Library/Frameworks/Python.framework/Versions/3.7/lib/python3.7/json/__init__.py", line 238, in dumps
    **kw).encode(obj)
  File "/Library/Frameworks/Python.framework/Versions/3.7/lib/python3.7/json/encoder.py", line 199, in encode
    chunks = self.iterencode(o, _one_shot=True)
  File "/Library/Frameworks/Python.framework/Versions/3.7/lib/python3.7/json/encoder.py", line 257, in iterencode
    return _iterencode(o, 0)
  File "/Users/davemagarian/PycharmProjects/Meme-Flask/venv/lib/python3.7/site-packages/flask/json/__init__.py", line 100, in default
    return _json.JSONEncoder.default(self, o)
  File "/Library/Frameworks/Python.framework/Versions/3.7/lib/python3.7/json/encoder.py", line 179, in default
    raise TypeError(f'Object of type {o.__class__.__name__} '
TypeError: Object of type Image is not JSON serializable
[2019-10-27 10:09:52] ERROR    Exception on /uploadajax [POST]
Traceback (most recent call last):
  File "/Users/davemagarian/PycharmProjects/Meme-Flask/venv/lib/python3.7/site-packages/flask/app.py", line 2446, in wsgi_app
    response = self.full_dispatch_request()
  File "/Users/davemagarian/PycharmProjects/Meme-Flask/venv/lib/python3.7/site-packages/flask/app.py", line 1951, in full_dispatch_request
    rv = self.handle_user_exception(e)
  File "/Users/davemagarian/PycharmProjects/Meme-Flask/venv/lib/python3.7/site-packages/flask/app.py", line 1820, in handle_user_exception
    reraise(exc_type, exc_value, tb)
  File "/Users/davemagarian/PycharmProjects/Meme-Flask/venv/lib/python3.7/site-packages/flask/_compat.py", line 39, in reraise
    raise value
  File "/Users/davemagarian/PycharmProjects/Meme-Flask/venv/lib/python3.7/site-packages/flask/app.py", line 1949, in full_dispatch_request
    rv = self.dispatch_request()
  File "/Users/davemagarian/PycharmProjects/Meme-Flask/venv/lib/python3.7/site-packages/flask/app.py", line 1935, in dispatch_request
    return self.view_functions[rule.endpoint](**req.view_args)
  File "/Users/davemagarian/PycharmProjects/Meme-Flask/app/views.py", line 199, in upldfile
    return jsonify(byte=combined)
  File "/Users/davemagarian/PycharmProjects/Meme-Flask/venv/lib/python3.7/site-packages/flask/json/__init__.py", line 370, in jsonify
    dumps(data, indent=indent, separators=separators) + "\n",
  File "/Users/davemagarian/PycharmProjects/Meme-Flask/venv/lib/python3.7/site-packages/flask/json/__init__.py", line 211, in dumps
    rv = _json.dumps(obj, **kwargs)
  File "/Library/Frameworks/Python.framework/Versions/3.7/lib/python3.7/json/__init__.py", line 238, in dumps
    **kw).encode(obj)
  File "/Library/Frameworks/Python.framework/Versions/3.7/lib/python3.7/json/encoder.py", line 199, in encode
    chunks = self.iterencode(o, _one_shot=True)
  File "/Library/Frameworks/Python.framework/Versions/3.7/lib/python3.7/json/encoder.py", line 257, in iterencode
    return _iterencode(o, 0)
  File "/Users/davemagarian/PycharmProjects/Meme-Flask/venv/lib/python3.7/site-packages/flask/json/__init__.py", line 100, in default
    return _json.JSONEncoder.default(self, o)
  File "/Library/Frameworks/Python.framework/Versions/3.7/lib/python3.7/json/encoder.py", line 179, in default
    raise TypeError(f'Object of type {o.__class__.__name__} '
TypeError: Object of type Image is not JSON serializable
[2019-10-27 10:10:55] ERROR    Exception on /uploadajax [POST]
Traceback (most recent call last):
  File "/Users/davemagarian/PycharmProjects/Meme-Flask/venv/lib/python3.7/site-packages/flask/app.py", line 2446, in wsgi_app
    response = self.full_dispatch_request()
  File "/Users/davemagarian/PycharmProjects/Meme-Flask/venv/lib/python3.7/site-packages/flask/app.py", line 1952, in full_dispatch_request
    return self.finalize_request(rv)
  File "/Users/davemagarian/PycharmProjects/Meme-Flask/venv/lib/python3.7/site-packages/flask/app.py", line 1967, in finalize_request
    response = self.make_response(rv)
  File "/Users/davemagarian/PycharmProjects/Meme-Flask/venv/lib/python3.7/site-packages/flask/app.py", line 2097, in make_response
    "The view function did not return a valid response. The"
TypeError: The view function did not return a valid response. The function either returned None or ended without a return statement.
[2019-10-27 10:11:27] ERROR    Exception on /uploadajax [POST]
Traceback (most recent call last):
  File "/Users/davemagarian/PycharmProjects/Meme-Flask/venv/lib/python3.7/site-packages/flask/app.py", line 2446, in wsgi_app
    response = self.full_dispatch_request()
  File "/Users/davemagarian/PycharmProjects/Meme-Flask/venv/lib/python3.7/site-packages/flask/app.py", line 1951, in full_dispatch_request
    rv = self.handle_user_exception(e)
  File "/Users/davemagarian/PycharmProjects/Meme-Flask/venv/lib/python3.7/site-packages/flask/app.py", line 1820, in handle_user_exception
    reraise(exc_type, exc_value, tb)
  File "/Users/davemagarian/PycharmProjects/Meme-Flask/venv/lib/python3.7/site-packages/flask/_compat.py", line 39, in reraise
    raise value
  File "/Users/davemagarian/PycharmProjects/Meme-Flask/venv/lib/python3.7/site-packages/flask/app.py", line 1949, in full_dispatch_request
    rv = self.dispatch_request()
  File "/Users/davemagarian/PycharmProjects/Meme-Flask/venv/lib/python3.7/site-packages/flask/app.py", line 1935, in dispatch_request
    return self.view_functions[rule.endpoint](**req.view_args)
  File "/Users/davemagarian/PycharmProjects/Meme-Flask/app/views.py", line 199, in upldfile
    return jsonify(byte=combined)
  File "/Users/davemagarian/PycharmProjects/Meme-Flask/venv/lib/python3.7/site-packages/flask/json/__init__.py", line 370, in jsonify
    dumps(data, indent=indent, separators=separators) + "\n",
  File "/Users/davemagarian/PycharmProjects/Meme-Flask/venv/lib/python3.7/site-packages/flask/json/__init__.py", line 211, in dumps
    rv = _json.dumps(obj, **kwargs)
  File "/Library/Frameworks/Python.framework/Versions/3.7/lib/python3.7/json/__init__.py", line 238, in dumps
    **kw).encode(obj)
  File "/Library/Frameworks/Python.framework/Versions/3.7/lib/python3.7/json/encoder.py", line 199, in encode
    chunks = self.iterencode(o, _one_shot=True)
  File "/Library/Frameworks/Python.framework/Versions/3.7/lib/python3.7/json/encoder.py", line 257, in iterencode
    return _iterencode(o, 0)
  File "/Users/davemagarian/PycharmProjects/Meme-Flask/venv/lib/python3.7/site-packages/flask/json/__init__.py", line 100, in default
    return _json.JSONEncoder.default(self, o)
  File "/Library/Frameworks/Python.framework/Versions/3.7/lib/python3.7/json/encoder.py", line 179, in default
    raise TypeError(f'Object of type {o.__class__.__name__} '
TypeError: Object of type Image is not JSON serializable
[2019-10-27 10:11:29] ERROR    Exception on /uploadajax [POST]
Traceback (most recent call last):
  File "/Users/davemagarian/PycharmProjects/Meme-Flask/venv/lib/python3.7/site-packages/flask/app.py", line 2446, in wsgi_app
    response = self.full_dispatch_request()
  File "/Users/davemagarian/PycharmProjects/Meme-Flask/venv/lib/python3.7/site-packages/flask/app.py", line 1951, in full_dispatch_request
    rv = self.handle_user_exception(e)
  File "/Users/davemagarian/PycharmProjects/Meme-Flask/venv/lib/python3.7/site-packages/flask/app.py", line 1820, in handle_user_exception
    reraise(exc_type, exc_value, tb)
  File "/Users/davemagarian/PycharmProjects/Meme-Flask/venv/lib/python3.7/site-packages/flask/_compat.py", line 39, in reraise
    raise value
  File "/Users/davemagarian/PycharmProjects/Meme-Flask/venv/lib/python3.7/site-packages/flask/app.py", line 1949, in full_dispatch_request
    rv = self.dispatch_request()
  File "/Users/davemagarian/PycharmProjects/Meme-Flask/venv/lib/python3.7/site-packages/flask/app.py", line 1935, in dispatch_request
    return self.view_functions[rule.endpoint](**req.view_args)
  File "/Users/davemagarian/PycharmProjects/Meme-Flask/app/views.py", line 199, in upldfile
    return jsonify(byte=combined)
  File "/Users/davemagarian/PycharmProjects/Meme-Flask/venv/lib/python3.7/site-packages/flask/json/__init__.py", line 370, in jsonify
    dumps(data, indent=indent, separators=separators) + "\n",
  File "/Users/davemagarian/PycharmProjects/Meme-Flask/venv/lib/python3.7/site-packages/flask/json/__init__.py", line 211, in dumps
    rv = _json.dumps(obj, **kwargs)
  File "/Library/Frameworks/Python.framework/Versions/3.7/lib/python3.7/json/__init__.py", line 238, in dumps
    **kw).encode(obj)
  File "/Library/Frameworks/Python.framework/Versions/3.7/lib/python3.7/json/encoder.py", line 199, in encode
    chunks = self.iterencode(o, _one_shot=True)
  File "/Library/Frameworks/Python.framework/Versions/3.7/lib/python3.7/json/encoder.py", line 257, in iterencode
    return _iterencode(o, 0)
  File "/Users/davemagarian/PycharmProjects/Meme-Flask/venv/lib/python3.7/site-packages/flask/json/__init__.py", line 100, in default
    return _json.JSONEncoder.default(self, o)
  File "/Library/Frameworks/Python.framework/Versions/3.7/lib/python3.7/json/encoder.py", line 179, in default
    raise TypeError(f'Object of type {o.__class__.__name__} '
TypeError: Object of type Image is not JSON serializable
[2019-10-27 10:25:25] ERROR    Exception on /uploadajax [POST]
Traceback (most recent call last):
  File "/Users/davemagarian/PycharmProjects/Meme-Flask/venv/lib/python3.7/site-packages/flask/app.py", line 2446, in wsgi_app
    response = self.full_dispatch_request()
  File "/Users/davemagarian/PycharmProjects/Meme-Flask/venv/lib/python3.7/site-packages/flask/app.py", line 1951, in full_dispatch_request
    rv = self.handle_user_exception(e)
  File "/Users/davemagarian/PycharmProjects/Meme-Flask/venv/lib/python3.7/site-packages/flask/app.py", line 1820, in handle_user_exception
    reraise(exc_type, exc_value, tb)
  File "/Users/davemagarian/PycharmProjects/Meme-Flask/venv/lib/python3.7/site-packages/flask/_compat.py", line 39, in reraise
    raise value
  File "/Users/davemagarian/PycharmProjects/Meme-Flask/venv/lib/python3.7/site-packages/flask/app.py", line 1949, in full_dispatch_request
    rv = self.dispatch_request()
  File "/Users/davemagarian/PycharmProjects/Meme-Flask/venv/lib/python3.7/site-packages/flask/app.py", line 1935, in dispatch_request
    return self.view_functions[rule.endpoint](**req.view_args)
  File "/Users/davemagarian/PycharmProjects/Meme-Flask/app/views.py", line 190, in upldfile
    x = imgByteArr.decode('utf-8')
UnicodeDecodeError: 'utf-8' codec can't decode byte 0x89 in position 0: invalid start byte
[2019-10-27 10:28:45] ERROR    Exception on /uploadajax [POST]
Traceback (most recent call last):
  File "/Users/davemagarian/PycharmProjects/Meme-Flask/venv/lib/python3.7/site-packages/flask/app.py", line 2446, in wsgi_app
    response = self.full_dispatch_request()
  File "/Users/davemagarian/PycharmProjects/Meme-Flask/venv/lib/python3.7/site-packages/flask/app.py", line 1951, in full_dispatch_request
    rv = self.handle_user_exception(e)
  File "/Users/davemagarian/PycharmProjects/Meme-Flask/venv/lib/python3.7/site-packages/flask/app.py", line 1820, in handle_user_exception
    reraise(exc_type, exc_value, tb)
  File "/Users/davemagarian/PycharmProjects/Meme-Flask/venv/lib/python3.7/site-packages/flask/_compat.py", line 39, in reraise
    raise value
  File "/Users/davemagarian/PycharmProjects/Meme-Flask/venv/lib/python3.7/site-packages/flask/app.py", line 1949, in full_dispatch_request
    rv = self.dispatch_request()
  File "/Users/davemagarian/PycharmProjects/Meme-Flask/venv/lib/python3.7/site-packages/flask/app.py", line 1935, in dispatch_request
    return self.view_functions[rule.endpoint](**req.view_args)
  File "/Users/davemagarian/PycharmProjects/Meme-Flask/app/views.py", line 191, in upldfile
    x =base64.b64encode(combined).decode('utf8')
  File "/Library/Frameworks/Python.framework/Versions/3.7/lib/python3.7/base64.py", line 58, in b64encode
    encoded = binascii.b2a_base64(s, newline=False)
TypeError: a bytes-like object is required, not 'Image'
[2019-10-27 10:29:18] ERROR    Exception on /uploadajax [POST]
Traceback (most recent call last):
  File "/Users/davemagarian/PycharmProjects/Meme-Flask/venv/lib/python3.7/site-packages/flask/app.py", line 2446, in wsgi_app
    response = self.full_dispatch_request()
  File "/Users/davemagarian/PycharmProjects/Meme-Flask/venv/lib/python3.7/site-packages/flask/app.py", line 1951, in full_dispatch_request
    rv = self.handle_user_exception(e)
  File "/Users/davemagarian/PycharmProjects/Meme-Flask/venv/lib/python3.7/site-packages/flask/app.py", line 1820, in handle_user_exception
    reraise(exc_type, exc_value, tb)
  File "/Users/davemagarian/PycharmProjects/Meme-Flask/venv/lib/python3.7/site-packages/flask/_compat.py", line 39, in reraise
    raise value
  File "/Users/davemagarian/PycharmProjects/Meme-Flask/venv/lib/python3.7/site-packages/flask/app.py", line 1949, in full_dispatch_request
    rv = self.dispatch_request()
  File "/Users/davemagarian/PycharmProjects/Meme-Flask/venv/lib/python3.7/site-packages/flask/app.py", line 1935, in dispatch_request
    return self.view_functions[rule.endpoint](**req.view_args)
  File "/Users/davemagarian/PycharmProjects/Meme-Flask/app/views.py", line 191, in upldfile
    x =base64.b64encode(saved_meme).decode('utf8')
  File "/Library/Frameworks/Python.framework/Versions/3.7/lib/python3.7/base64.py", line 58, in b64encode
    encoded = binascii.b2a_base64(s, newline=False)
TypeError: a bytes-like object is required, not '_io.BytesIO'
[2019-10-27 10:29:50] ERROR    Exception on /uploadajax [POST]
Traceback (most recent call last):
  File "/Users/davemagarian/PycharmProjects/Meme-Flask/venv/lib/python3.7/site-packages/flask/app.py", line 2446, in wsgi_app
    response = self.full_dispatch_request()
  File "/Users/davemagarian/PycharmProjects/Meme-Flask/venv/lib/python3.7/site-packages/flask/app.py", line 1951, in full_dispatch_request
    rv = self.handle_user_exception(e)
  File "/Users/davemagarian/PycharmProjects/Meme-Flask/venv/lib/python3.7/site-packages/flask/app.py", line 1820, in handle_user_exception
    reraise(exc_type, exc_value, tb)
  File "/Users/davemagarian/PycharmProjects/Meme-Flask/venv/lib/python3.7/site-packages/flask/_compat.py", line 39, in reraise
    raise value
  File "/Users/davemagarian/PycharmProjects/Meme-Flask/venv/lib/python3.7/site-packages/flask/app.py", line 1949, in full_dispatch_request
    rv = self.dispatch_request()
  File "/Users/davemagarian/PycharmProjects/Meme-Flask/venv/lib/python3.7/site-packages/flask/app.py", line 1935, in dispatch_request
    return self.view_functions[rule.endpoint](**req.view_args)
  File "/Users/davemagarian/PycharmProjects/Meme-Flask/app/views.py", line 202, in upldfile
    return jsonify(byte=combined)
  File "/Users/davemagarian/PycharmProjects/Meme-Flask/venv/lib/python3.7/site-packages/flask/json/__init__.py", line 370, in jsonify
    dumps(data, indent=indent, separators=separators) + "\n",
  File "/Users/davemagarian/PycharmProjects/Meme-Flask/venv/lib/python3.7/site-packages/flask/json/__init__.py", line 211, in dumps
    rv = _json.dumps(obj, **kwargs)
  File "/Library/Frameworks/Python.framework/Versions/3.7/lib/python3.7/json/__init__.py", line 238, in dumps
    **kw).encode(obj)
  File "/Library/Frameworks/Python.framework/Versions/3.7/lib/python3.7/json/encoder.py", line 199, in encode
    chunks = self.iterencode(o, _one_shot=True)
  File "/Library/Frameworks/Python.framework/Versions/3.7/lib/python3.7/json/encoder.py", line 257, in iterencode
    return _iterencode(o, 0)
  File "/Users/davemagarian/PycharmProjects/Meme-Flask/venv/lib/python3.7/site-packages/flask/json/__init__.py", line 100, in default
    return _json.JSONEncoder.default(self, o)
  File "/Library/Frameworks/Python.framework/Versions/3.7/lib/python3.7/json/encoder.py", line 179, in default
    raise TypeError(f'Object of type {o.__class__.__name__} '
TypeError: Object of type Image is not JSON serializable
